Workbook

Sheet Home
B1: AUDIT CHECK LISTS
B3: Client Name : | C3: Thandanani Transport
G4: =TEXT(AVERAGE('General & Financials'!E6,'Management Control'!D6,'Skills Development'!D6,'Preferential Procurement'!D6,'Enterprise Development'!D6,'Supplier Development'!D6,'Socio-economic Development'!D6),"0%")&" "&"of documents have been received" -> 49% of documents have been received | K4: =TEXT(COUNTIFS('Audit Schedule'!G5:G15,"Completed")/COUNTA('Audit Schedule'!G5:G15),"0%")&" "&"of Audit Schedule tasks completed" -> 0% of Audit Schedule tasks completed
B5: Financial Period :
B6: Start ► | C6: 45352 | D6: =IF(C6="","Null",C6) -> 45352
B7: End ► | C7: 45716 | D7: =IF(C7="","Null",IF(AND(C7-C6>355,C7-C6<366),C7-C6,0)) -> 364 | L7: =IF($C$8="",IF($C$7<TODAY(),"Please capture either the Financial Year End or the Audit Date","Time left before Financial Year End"),"Time left before Audit Date") -> Time left before Audit Date
B8: Audit Date ► | C8: 46029 | D8: =IF(C8="","Null",IF(C8-C7<0,0,C8-C7)) -> 313 | K8: =IF($C$7="","Please capture Finacial Year End Date",IF(AND($C$7<TODAY(),$C$8=""),"Please capture Audit Date!",IF(AND($C$7>TODAY(),$C$8=""),TEXT($C$7-TODAY(),"0.00")/30,IF($C$8="","Please capture Audit Date!",TEXT($C$8-TODAY(),"0.00")/30)))) -> #VALUE! | L8: =IF($K$8<=1,"Month","Months") -> #VALUE! | M8: or;
K9: =IF($C$7="","Please capture Finacial Year End Date",IF(AND($C$7<TODAY(),$C$8=""),"Please capture Audit Date!",IF(AND($C$7>TODAY(),$C$8=""),INT($C$7-TODAY())/7,IF($C$8="","Please capture Audit Date!",INT($C$8-TODAY())/7)))) -> 3.7142857 | L9: =IF($K$9<=1,"Week","Weeks") -> Weeks | M9: or;
C10: Quick Links to checklists | K10: =IF($C$7="","Please capture Finacial Year End Date",IF(AND($C$7<TODAY(),$C$8=""),"Please capture Audit Date!",IF(AND($C$7>TODAY(),$C$8=""),NETWORKDAYS(TODAY(),Home!$C$7,Holidays8[Dates]),IF($C$8="","Please capture Audit Date!",NETWORKDAYS(TODAY(),Home!$C$8,Holidays8[Dates]))))) -> 19 | L10: =IF($K$10<=1,"Business Day","Business Days") -> Business Days
C11: General & Finances
C12: Ownership
C13: Management Control
C14: Skills Development
C15: Preferential Procurement
C16: Enterprise Development
C17: Supplier Development
C18: Socio-economic Development

Sheet Audit Schedule
B4: COUNT | C4: AUDIT TASK | D4: RESPONSIBLE PARTY | E4: START DATE | F4: DUE DATE | G4: STATUS | H4: COMMENTS
B5: =ROW(A1) -> 1 | C5: Preparing audit file and collecting data | D5: Okiru | E5: 46000 | F5: 46008 | G5: Pending
B6: =ROW(A2) -> 2 | C6: Updating audit submission packs | D6: Okiru | E6: 46000 | F6: 46008 | G6: Pending
B7: =ROW(A3) -> 3 | C7: Finalize audit submission packs and send to VA for sampling | D7: Okiru | E7: 46000 | F7: 46008 | G7: Pending
B8: =ROW(A4) -> 4 | C8: Thandanani Transport to send sample selection | D8: Thandanani | E8: 46006 | F8: 46008 | G8: Pending
B9: =ROW(A5) -> 5 | C9: Okiru to send checklist of sampled data and documents required | D9: Okiru | E9: 46000 | F9: 46003 | G9: Pending
B10: =ROW(A6) -> 6 | C10: Send supporting documents for sampled data on the dropbox link provided | D10: Thandanani | E10: 46006 | F10: 46008 | G10: Pending
B11: =ROW(A7) -> 7 | C11: Review of audit file and preliminary audit | D11: Okiru | E11: 46000 | F11: 46008 | G11: Pending
B12: =ROW(A8) -> 8 | C12: Onsite BEE audit | D12: BEE Online | E12: 46029 | F12: 46029 | G12: Pending
B13: =ROW(A9) -> 9 | C13: VA to send review notes | D13: BEE Online | E13: 46029 | F13: 46031 | G13: Pending
B14: =ROW(A10) -> 10 | C14: Sending outstanding requirements to Okiru, if any | D14: Thandanani | E14: 46006 | F14: 46008 | G14: Pending
B15: =ROW(A11) -> 11 | C15: Issue BEE certificate | D15: BEE Online | E15: 46029 | F15: 46037 | G15: Pending

Sheet General & Financials
B1: =Home!C3&" "&"Audit - General Documentation Checklist" -> Thandanani Transport Audit - General Documentation Checklist
B3: =IF(Home!$C$8="",IF(Home!$C$7<TODAY(),"Please capture either the Financial Year End or the Audit Date","Time left before Financial Year End"),"Time left before Audit Date") -> Time left before Audit Date
B4: =Home!K8 -> #VALUE! | C4: =IF($J$8<=1,"Month Or;","Months Or;") -> Month Or;
B5: =Home!K9 -> 3.7142857 | C5: =IF($J$9<=1,"Week Or;","Weeks Or;") -> Week Or; | E5: Documents Received
B6: =Home!K10 -> 19 | C6: =IF($J$11<=1,"Business Day","Business Days") -> Business Day | E6: =COUNTIF(General[Status],"Received")/COUNTA(General[[Description ]]) -> 0.8
C9: Count | D9: Pillar | E9: Description | F9: Status | G9: Comment
C10: =ROW(A1) -> 1 | D10: General | E10: Company Profile | F10: Received
C11: =ROW(A2) -> 2 | D11: General | E11: Valid Tax Clearance Certificate | F11: Received
C12: =ROW(A3) -> 3 | D12: General | E12: Management representation letter | F12: Outstanding | G12: Management Rep letter to be drafted
C13: =ROW(A4) -> 4 | D13: General | E13: CIPC document printed within the last 3 months | F13: Received
C14: =ROW(A5) -> 5 | D14: General | E14: Audited Financial Statements for year under review | F14: Received | G14: Financial are not Audited

Sheet Management Control
B1: =Home!C3&" "&"Audit - Management Control Checklist" -> Thandanani Transport Audit - Management Control Checklist | T1: =COUNTIF(Management_1[Status],"Received")/(COUNTA(Management_1[Count])-COUNTIF(Management_1[Status],"N/A")) -> 0.16666667 | U1: =COUNTIF(Management_2[[Interview]:[Disabled doc note]],"Received")/(5*COUNTA(Management_2[Count])-COUNTIF(Management_2[[Interview]:[Disabled doc note]],"N/A")) -> 0.2
B3: =IF(Home!$C$8="",IF(Home!$C$7<TODAY(),"Please capture either the Financial Year End or the Audit Date","Time left before Financial Year End"),"Time left before Audit Date") -> Time left before Audit Date
B4: =Home!K8 -> #VALUE! | C4: =IF($I$8<=1,"Month Or;","Months Or;") -> Month Or;
B5: =Home!K9 -> 3.7142857 | C5: =IF(#REF!<=1,"Week Or;","Weeks Or;") -> #REF! | D5: Total Documents Received
B6: =Home!K10 -> 19 | C6: =IF(#REF!<=1,"Business Day","Business Days") -> #REF! | D6: =AVERAGE(T1,U1) -> 0.18333333
B8: Count | C8: Description | D8: Status | E8: Comment
B9: =ROW(B5) -> 5 | C9: Company Organogram | D9: Outstanding | E9: Okiru to draft and send to TT to sign
B10: =ROW(B7) -> 7 | C10: EEA1 | D10: Outstanding
B11: =ROW(B5) -> 5 | C11: Signed employment contracts | D11: Outstanding | E11: Okiru to draft and send to TT to sign
B12: =ROW(B5) -> 5 | C12: Most recent payslip | D12: Outstanding
B13: =ROW(B6) -> 6 | C13: Job description | D13: Outstanding | E13: TT to provide
B14: =ROW(B7) -> 7 | C14: Certified ID copy | D14: Received
B16: Sampled Management Control
B17: Count | C17: Name of Individual: | D17: Management Level | E17: Race | F17: Gender | G17: Interview | H17: Certified ID copy | I17: Payslip | J17: Employment contract | K17: EEA1 Form | L17: Disabled doc note
B18: =ROW(A1) -> 1 | C18: Venugopal Lutchman, Naidoo | D18: Senior Top Management | E18: A | F18: M | G18: Outstanding | H18: Received | I18: Outstanding | J18: Outstanding | K18: Outstanding
B21: Required Documents: | C21: Reference | D21: Feedback | E21: Comments

Sheet Skills Development
B1: =Home!C3&" "&"Audit - Skills Development Checklist" -> Thandanani Transport Audit - Skills Development Checklist | W1: =COUNTIF(Skills_1[Status],"Received")/(COUNTA(Skills_1[Count])-COUNTIF(Skills_1[Status],"N/A")) -> 0.4 | X1: =COUNTIF(Skills_2[[Proof of attendance]:[Certified ID copy]],"Received")/(4*COUNTA(Skills_2[Count])-COUNTIF(Skills_2[[Proof of attendance]:[Certified ID copy]],"N/A")) -> 0.25 | Y1: =COUNTIF(Skills_3[[Proof of attendance]:[EEA1 Form]],"Received")/(8*COUNTA(Skills_3[Count])-COUNTIF(Skills_3[[Proof of attendance]:[EEA1 Form]],"N/A")) -> 0.125 | Z1: =COUNTIF(Skills_4[Invoices],"Received")/(COUNTA(Skills_4[Count])-COUNTIF(Skills_4[Invoices],"N/A")) -> 0
B3: =IF(Home!$C$8="",IF(Home!$C$7<TODAY(),"Please capture either the Financial Year End or the Audit Date","Time left before Financial Year End"),"Time left before Audit Date") -> Time left before Audit Date
B4: =Home!K8 -> #VALUE! | C4: =IF($J$8<=1,"Month Or;","Months Or;") -> Month Or;
B5: =Home!K9 -> 3.7142857 | C5: =IF($J$9<=1,"Week Or;","Weeks Or;") -> Week Or; | D5: Total Documents Received
B6: =Home!K10 -> 19 | C6: =Home!L10 -> Business Days | D6: =AVERAGE(W1:Z1) -> 0.19375
B8: Count | C8: Description | D8: Status | E8: Comment
B9: =ROW(A1) -> 1 | C9: WSP and ATR (showing Priority Skills Programme) | D9: Outstanding
B10: =ROW(A2) -> 2 | C10: Proof of WSP submission to SETA | D10: Received
B11: =ROW(A3) -> 3 | C11: Proof of WSP Approval from SETA | D11: Outstanding
B12: =ROW(A4) -> 4 | C12: EMP201s for the measurement period | D12: Received
B13: =ROW(A5) -> 5 | C13: Learnership Tracking Tool | D13: Outstanding
B16: General Training
B17: Count | C17: Training | D17: Course / Education Detail | E17: Category | F17: Total Costs Incurred | G17: Race | H17: Gender | I17: Proof of attendance | J17: Proof of payment | K17: Invoice | L17: Certified ID copy | M17: Bursary Contract
B18: =ROW(A1) -> 1 | C18: Hlengiwe Hadebe | D18: Disables Candidate Bursary Programme | F18: 27000 | G18: A | H18: F | I18: Received | J18: Received | K18: Received | L18: Received | M18: Received
B19: =ROW(A2) -> 2 | I19: Outstanding | J19: Outstanding | K19: Outstanding | L19: Outstanding | M19: Outstanding
B20: =ROW(A3) -> 3 | I20: Outstanding | J20: Outstanding | K20: Outstanding | L20: Outstanding | M20: Outstanding
B21: =ROW(A4) -> 4 | I21: Outstanding | J21: Outstanding | K21: Outstanding | L21: Outstanding | M21: Outstanding
B24: Learnerships
B25: Count | C25: Name | D25: Type | E25: Race | F25: Gender | G25: Course Cost | H25: Stipend | I25: Proof of attendance | J25: Invoice | K25: Proof of payment | L25: ID copy | M25: Salary Report | N25: SETA Agreement | O25: Proof of absorbtion | P25: Unemployed Affidavit or HR Letter | Q25: EEA1 Form | R25: Disabled doc note
B26: =ROW(B1) -> 1 | C26: Thando Dlamimi | E26: A | F26: F | G26: 7000 | H26: 6000 | I26: Received | J26: Outstanding | K26: Outstanding | L26: Received | M26: Outstanding | N26: Outstanding | O26: Outstanding | P26: Outstanding | Q26: Outstanding | R26: Outstanding
B27: =ROW(B2) -> 2 | C27: Lindokuhle Nkosi | E27: A | F27: M | G27: 68500 | H27: 6000 | I27: Outstanding | J27: Outstanding | K27: Received | L27: Received | M27: Outstanding | N27: Received | O27: Outstanding | P27: Outstanding | Q27: Received | R27: Received
B28: =ROW(B3) -> 3 | C28: Lindokuhle Nkosi | E28: A | F28: M | G28: 7000 | H28: 6000 | I28: Outstanding | J28: Outstanding | K28: Received | L28: Received | M28: Outstanding | N28: Received | O28: Outstanding | P28: Outstanding | Q28: Outstanding | R28: Outstanding
B29: =ROW(B4) -> 4 | I29: Outstanding | J29: Outstanding | K29: Outstanding | L29: Outstanding | M29: Outstanding | N29: Outstanding | O29: Outstanding | P29: Outstanding | Q29: Outstanding | R29: Outstanding
B30: =ROW(B5) -> 5 | I30: Outstanding | J30: Outstanding | K30: Outstanding | L30: Outstanding | M30: Outstanding | N30: Outstanding | O30: Outstanding | P30: Outstanding | Q30: Outstanding | R30: Outstanding
B31: =ROW(B6) -> 6 | I31: Outstanding | J31: Outstanding | K31: Outstanding | L31: Outstanding | M31: Outstanding | N31: Outstanding | O31: Outstanding | P31: Outstanding | Q31: Outstanding | R31: Outstanding
B32: =ROW(B7) -> 7 | I32: Outstanding | J32: Outstanding | K32: Outstanding | L32: Outstanding | M32: Outstanding | N32: Outstanding | O32: Outstanding | P32: Outstanding | Q32: Outstanding | R32: Outstanding
B33: =ROW(B8) -> 8 | I33: Outstanding | J33: Outstanding | K33: Outstanding | L33: Outstanding | M33: Outstanding | N33: Outstanding | O33: Outstanding | P33: Outstanding | Q33: Outstanding | R33: Outstanding
B34: =ROW(B9) -> 9 | I34: Outstanding | J34: Outstanding | K34: Outstanding | L34: Outstanding | M34: Outstanding | N34: Outstanding | O34: Outstanding | P34: Outstanding | Q34: Outstanding | R34: Outstanding
B36: Trainers (SDF)
B37: Count | C37: Name | D37: Amount | E37: Invoices | F37: POP
B38: =ROW(B1) -> 1 | E38: Outstanding | F38: Outstanding
C40: Skills Development
C42: Required Documents: | D42: Reference
C43: Workplace Skills Plan/Annual Training Report, | D43: SD-01
C44: SETA Confrmation of approval of the Workplace Skills Plan and Annual Training Report | D44: SD-02
C45: Confirmation from the SETA of Registration of a Skills Development Facilitator, | D45: SD-03
C46: Proof of Implementation of a priority skill as per SETA. Print Priority skills list from SETA and provide invoice of course implemented within business and proof of attendance to demonstrate implementation, | D46: SD-04
C47: EMPSA for the financial period | D47: SD-05
C48: A letter which includes a reconciliation of the Leviable Amount and the Total Staff costs to explain which other amounts had caused the difference. | D48: SD-06
C50: Bursaries Expenditure | D50: Reference
...

Sheet Preferential Procurement
B1: =Home!C3&" "&"Audit - Preferential Procurement Checklist" -> Thandanani Transport Audit - Preferential Procurement Checklist | AB1: =COUNTIF(Procurement[Status],"Received")/(COUNTA(Procurement[Count])-COUNTIF(Procurement[Status],"N/A")) -> 0.5 | AC1: =COUNTIF(Procurement_1[[BEE Certificate]:[Supplier Ledger for 12 months period]],"Received")/(4*COUNTA(Procurement_1[Count])-COUNTIF(Procurement_1[[BEE Certificate]:[Supplier Ledger for 12 months period]],"N/A")) -> 0.83333333 | AD1: =COUNTIF(Procurement_2[[Highest Invoice in 2018]:[Supplier spend report as printed from the system (2018 FY)]],"Received")/(5*COUNTA(Procurement_2[Count])-COUNTIF(Procurement_2[[Highest Invoice in 2018]:[Supplier spend report as printed from the system (2018 FY)]],"N/A")) -> 0
B3: =IF(Home!$C$8="",IF(Home!$C$7<TODAY(),"Please capture either the Financial Year End or the Audit Date","Time left before Financial Year End"),"Time left before Audit Date") -> Time left before Audit Date
B4: =Home!K8 -> #VALUE! | C4: =IF($J$11<=1,"Month Or;","Months Or;") -> Month Or;
B5: =Home!K9 -> 3.7142857 | C5: =IF($M$12<=1,"Week Or;","Weeks Or;") -> Weeks Or; | D5: Total Documents Received
B6: =Home!K10 -> 19 | C6: =IF(B6<=1,"Business Day","Business Days") -> Business Days | D6: =AVERAGE(AB1:AD1) -> 0.44444444
B7: Count | C7: Description | D7: Status | E7: Comment
B8: =ROW(A1) -> 1 | C8: Management representation letter confirming reason for exclusion | D8: Outstanding | E8: Okiru to draft
B9: =ROW(A2) -> 2 | C9: TMPS Calc | D9: Received
B11: SAMPLE - LOCAL
B12: Count | C12: Supplier Selection: | D12: Spend | E12: Classification | F12: Level | G12: 51% BO? | H12: 30% BWO? | I12: 51% BDG? | J12: BEE Certificate | K12: Highest Invoice | L12: Proofs of payment relating to those invoices | M12: VAT no. / Reg no. of BEE certificate match Invoice? | N12: Supplier Ledger for 12 months period
B13: =ROW(A1) -> 1 | C13: BP Edenvale | D13: 1672231 | E13: Generic | F13: Level 1 | J13: Received | K13: Received | L13: Received | M13: Received | N13: Received
B14: =ROW(A2) -> 2 | C14: Outsurance | D14: 112300 | E14: Generic | F14: Level 1 | J14: Pending | K14: Pending | L14: Received | M14: Outstanding | N14: Received
B15: =ROW(A3) -> 3 | C15: Provident Fund (FUTURASA) | D15: 334878 | E15: QSE | F15: Level 2 | J15: Outstanding | K15: Received | L15: Received | M15: Outstanding | N15: Received
B16: =ROW(A4) -> 4 | C16: TST Truc Chassis | D16: 57812 | E16: QSE | F16: Level 1 | J16: Received | K16: Received | L16: Received | M16: Received | N16: Received
B17: =ROW(A5) -> 5 | C17: Ekurhuleni Municipality | D17: 288696
B18: 5 | C18: Subbiah Enterprises | D18: 120589 | E18: EME | F18: Level 1 | J18: Received | K18: Received | L18: Received | M18: Received | N18: Received
B21: SAMPLE - FOREIGN
B22: Count | C22: Supplier Selection: | D22: Spend | E22: Highest Invoice in 2018 | F22: Proofs of payment relating to the invoice | G22: 12 months Supplier Ledger (2018) | H22: Supplier spend report as printed from the system (2018 FY)
B23: =ROW(A1) -> 1 | E23: Outstanding | F23: Outstanding | G23: Outstanding | H23: Outstanding
C27: Preferential Procurement
C29: Local Spend | D29: Reference
C30: Required Documents:
C31: Valid B-BBEE Verification Certificates / Affidavit of suppliers. For Construcion Entities ensure that a Construction Affidavit or Certificate issued by a SANAS accredited Agency. For Transport Companies ensure that a Certificate issued by a SANAS accredited Agency is obtained
C32: Supplier Detailed Ledger (in Excel and Highlight the invoices Received on the Ledger and ensure Totals are included and these totals are excluding VAT)
C33: 5 invoices received from the sampled supplier within the financial period
C34: Vendor Loading Portal, Ledger and First Invoice for First Time Suppliers
C35: Sample of 3 year Contracts for Supplier Development Beneficiary
C36: Sample of 3 year Contracts with Black Owned EME/QSE

Sheet Sheet1
A1: Large
A2: QSE
A3: EME

Sheet Supplier Development
B1: =Home!C3&" "&"Audit - Gsupplier Development Checklist" -> Thandanani Transport Audit - Gsupplier Development Checklist | Y1: =COUNTIF(SupplierDev_1[[EME Affidavit]:[Signed Emplyees Timesheets]],"Received")/(10*COUNTA(SupplierDev_1[Count])-COUNTIF(SupplierDev_1[[EME Affidavit]:[Signed Emplyees Timesheets]],"N/A")) -> 0.8
B3: =IF(Home!$C$8="",IF(Home!$C$7<TODAY(),"Please capture either the Financial Year End or the Audit Date","Time left before Financial Year End"),"Time left before Audit Date") -> Time left before Audit Date
B4: =Home!K8 -> #VALUE! | C4: =IF($J$8<=1,"Month Or;","Months Or;") -> Month Or;
B5: =Home!K9 -> 3.7142857 | C5: =IF(B5<=1,"Week Or;","Weeks Or;") -> Weeks Or; | D5: Total Documents Received
B6: =Home!K10 -> 19 | C6: =IF(B6<=1,"Business Day","Business Days") -> Business Days | D6: =AVERAGE(Y1) -> 0.8
B9: Count | C9: Beneficiary | D9: Support | E9: Amount | F9: BEE certificate / Affidavit | G9: EME Affidavit | H9: ED agreement | I9: SD Confirmation | J9: Lease Agreement | K9: Calculations (on Excel) | L9: Attendance Register | M9: ID copy | N9: Proof of Payment | O9: Invoice | P9: Signed Emplyees Timesheets | Q9: Supplier Ledger
B10: =ROW(B1) -> 1 | C10: Isibani Chartered accountants | G10: Outstanding | H10: N/A | I10: Received | J10: N/A | K10: Received | L10: N/A | M10: N/A | N10: Received | O10: Received | P10: N/A | Q10: N/A
B11: =ROW(B2) -> 2 | G11: N/A | H11: N/A | I11: N/A | J11: N/A | K11: N/A | L11: N/A | M11: N/A | N11: N/A | O11: N/A | P11: N/A | Q11: N/A
C14: Supplier Development
C17: SUPPLIER DEVELOPMENT
C19: Required Documents:
C20: Supplier Development Agreement with ultimate Beneficiary | D20: SuD-01
C21: Acknowledgement Letter or Receipt from beneficiary stating what was type of assistance was received | D21: SuD-02
C22: Affidavit Signed by a Commissioner of Oaths for Beneficiary Entity or BEE Certificate - EME/QSE values BO. Ensure that a Construction Sector Affidavit/Certificate issued by a SANAS accredited Agency is provided for Construction Sector Beneficiaries and that a Certificate issued by a SANAS Accredited Agency is provided for a Transport Sector Beneficiary | D22: SuD-03
C23: Copies of invoices and related proof of payment for Direct Costs and Grants | D23: SuD-09
C24: Confirmation of Graduation (Previous proof of ED contributions, ED Agreement, Affidavit, letter & POP) | D24: SuD-13
C25: Vendor listing - proof when supplier loaded, ledger, 1st invoice | D25: SuD-14
C26: Confirmation of Job Creation | D26: SuD-15.1
C27: Payroll Report of the Beneficiary Entity indicating commencement dates of all employees | D27: SuD-15.2
C30: SHORTER PAYMENT PERIOD:
C31: Required Documents: | D31: Reference
C32: Supplier Development Agreement | D32: SuD-01
C33: Affidavit | D33: SuD-03
C34: Invoice | D34: SuD-09.1
C35: Proof of Payment (In the form of EFT Confirmations or printout from Bank statements) | D35: SuD-09.2

Sheet Enterprise Development
B1: =Home!C3&" "&"Audit - Enterprise Development Checklist" -> Thandanani Transport Audit - Enterprise Development Checklist | W1: =COUNTIF(EnterpriseDev_1[[EME Affidavit]:[Signed GL (@31 Dec 2018)]],"Received")/(5*COUNTA(EnterpriseDev_1[Count])-COUNTIF(EnterpriseDev_1[[EME Affidavit]:[Signed GL (@31 Dec 2018)]],"N/A")) -> 0.4
B3: =IF(Home!$C$8="",IF(Home!$C$7<TODAY(),"Please capture either the Financial Year End or the Audit Date","Time left before Financial Year End"),"Time left before Audit Date") -> Time left before Audit Date
B4: =Home!K8 -> #VALUE! | C4: =IF($H$8<=1,"Month Or;","Months Or;") -> Month Or;
B5: =Home!K9 -> 3.7142857 | C5: =IF(B5<=1,"Week Or;","Weeks Or;") -> Weeks Or; | D5: Total Documents Received
B6: =Home!K10 -> 19 | C6: =IF(B6<=1,"Business Day","Business Days") -> Business Days | D6: =AVERAGE(W1) -> 0.4
B9: Count | C9: Beneficiary | D9: Support | E9: Actual Spend | F9: Recognised Spend | G9: EME Affidavit | H9: ED agreement | I9: ED Confirmation | J9: Proof of payment2 | K9: Signed GL (@31 Dec 2018) | L9: Number of Jobs Created
B10: =ROW(B1) -> 1 | C10: Grenex | D10: Grant | E10: 150415.64 | G10: Outstanding | H10: Received | I10: Received | J10: Received | K10: Outstanding | L10: Outstanding
B11: =ROW(B2) -> 2 | C11: Kasi Fibre | D11: Grant | E11: 10000 | G11: Outstanding | H11: Outstanding | I11: Outstanding | J11: Received | K11: Outstanding | L11: Outstanding
G13: ED-03.1 | H13: ED-01.1 | I13: ED-09.1 | L13: ED-15.1
C14: Enterprise Development
C17: Enterprise DEVELOPMENT
C19: Required Documents:
C20: Enterprise Development Agreement with ultimate Beneficiary | D20: ED-01
C21: Acknowledgement Letter or Receipt from beneficiary stating what was type of assistance was received | D21: ED-02
C22: Affidavit Signed by a Commissioner of Oaths for Beneficiary Entity or BEE Certificate - EME/QSE values BO. Ensure that a Construction Sector Affidavit/Certificate issued by a SANAS accredited Agency is provided for Construction Sector Beneficiaries and that a Certificate issued by a SANAS Accredited Agency is provided for a Transport Sector Beneficiary | D22: ED-03
C23: Copies of invoices and related proof of payment for Direct Costs and Grants | D23: ED-09
C24: Confirmation of Job Creation | D24: ED-15.1
C25: Payroll Report of the Beneficiary Entity indicating commencement dates of all employees | D25: ED-15.2

Sheet Socio-economic Development
B1: =Home!C3&" "&"Audit - Gsupplier Development Checklist" -> Thandanani Transport Audit - Gsupplier Development Checklist | AA1: =COUNTIF(Socio_1[[Signed letter of confirmation with black beneficiary %]:[Proof of payment]],"Received")/(4*COUNTA(Socio_1[Count])-COUNTIF(Socio_1[[Signed letter of confirmation with black beneficiary %]:[Proof of payment]],"N/A")) -> 0.625
B3: =IF(Home!$C$8="",IF(Home!$C$7<TODAY(),"Please capture either the Financial Year End or the Audit Date","Time left before Financial Year End"),"Time left before Audit Date") -> Time left before Audit Date
B4: =Home!K8 -> #VALUE! | C4: =IF($K$8<=1,"Month Or;","Months Or;") -> Month Or;
B5: =Home!K9 -> 3.7142857 | C5: =IF($M$9<=1,"Week Or;","Weeks Or;") -> Week Or; | D5: Total Documents Received
B6: =Home!K10 -> 19 | C6: =IF($M$10<=1,"Business Day","Business Days") -> Business Day | D6: =AVERAGE(AA1) -> 0.625
B9: Count | C9: Beneficiary | D9: Support | E9: % Black beneficiary | F9: Actual Spend | G9: Recognised Spend | H9: Signed letter of confirmation with black beneficiary % | I9: 3rd person report regarding black beneficiary | J9: Invoice | K9: Proof of payment | L9: Acknowledgement Letter of reciept
B10: =ROW(B1) -> 1 | C10: Essentially Edenvale | D10: Grant | E10: 1 | F10: 500 | H10: Outstanding | I10: Outstanding | J10: Received | K10: Received | L10: Outstanding
B11: =ROW(B2) -> 2 | C11: OUTA | D11: Grant | E11: 1 | F11: 400 | H11: Received | J11: Received | K11: Received | L11: Outstanding
B12: =ROW(B2) -> 2 | C12: OUTA | D12: Grant | E12: 1 | F12: 400 | H12: Received | J12: Received | K12: Received | L12: Outstanding
B13: =ROW(B2) -> 2 | C13: Essentially Edenvale | D13: Grant | E13: 1 | F13: 500 | H13: Outstanding | I13: Outstanding | J13: Received | K13: Received | L13: Outstanding
H15: SED-01.1 | I15: SED-02.1 | J15: SED-04.1 | L15: SED-02.1
C16: Socio-Economic Development
C18: Required Documents: | D18: Reference | E18: Comment
C19: Affidavit/signed declaration from beneficiary stating what % benefit passed onto black people
C20: Beneficiary to provide Signed Acknowledgment Letter confirming the type and value of assistance received
C21: Independent Third Persons Report | E21: Okiru to draft the letter
C22: Copies of invoices and Proof of Payments for Grants and Direct Cost Contributions

Sheet Sheet2
C3: General | D3: ='General & Financials'!E6 -> 0.8
C4: Management Control | D4: ='Management Control'!D6 -> 0.18333333
C5: Skills Development | D5: ='Skills Development'!D6 -> 0.19375
C6: Preferential Procurement | D6: ='Preferential Procurement'!D6 -> 0.44444444
C7: Enterprise Development | D7: ='Enterprise Development'!D6 -> 0.4
C8: Supplier Development | D8: ='Supplier Development'!D6 -> 0.8
C9: Socio-economic Development | D9: ='Socio-economic Development'!D6 -> 0.625

Sheet Public Holidays
A1: Holidays
A2: 42737 | B2: New Years Day
A3: 42815 | B3: Human Rights Day
A4: 42839 | B4: Good Friday
A5: 42842 | B5: Family Day
A6: 42852 | B6: Freedom Day
A7: 42856 | B7: Workers Day
A8: 42902 | B8: Youth Day
A9: 42956 | B9: National Women’s Day
A10: 43003 | B10: Heritage Day
A11: 43085 | B11: Day of Reconciliation
A12: 43094 | B12: Christmas Day
A13: 43095 | B13: Day Of Goodwill

Sheet Sheet4
A1: Dates | B1: Holiday
A2: 42737 | B2: New Years Day
A3: 42815 | B3: Human Rights Day
A4: 42839 | B4: Good Friday
A5: 42842 | B5: Family Day
A6: 42852 | B6: Freedom Day
A7: 42856 | B7: Workers Day
A8: 42902 | B8: Youth Day
A9: 42956 | B9: National Women’s Day
A10: 43003 | B10: Heritage Day
A11: 43085 | B11: Day of Reconciliation
A12: 43094 | B12: Christmas Day
A13: 43095 | B13: Day Of Goodwill
... A36: 43460 | B36: Day Of Goodwill
