Workbook

Sheet Cover
A1: 🌱 SG CONSUMER | OKIRU ESG INTELLIGENCE TOOLKIT v1.6 | Net-Zero Edition
A2: King V · IFRS S1/S2 · GARP/GRAP · ISO 14001/45001/27001/26000 · GRI · EEA · WSP/ATR · SBTi CNZS 2.0 | Powered by Okiru Consulting
A4: ENTITY INFORMATION
B5: Entity | C5: SG Consumer / SuperGroup SG Consumer (Pty) Ltd
B6: Reporting Period | C6: FY 2025/2026 | July 2025 – June 2026
B7: Reporting Consultant | C7: Okiru Consulting | www.okiru.co.za
B8: Version | C8: v1.7 | May 2026 | SG Consumer Live Data Load (Coba submission)
B9: Last Updated | C9: 2026-05-27
B10: Baseline Year (for SBTi) | C10: FY 2025/26
B11: Net-Zero Target Year | C11: 2050 (SBTi CNZS 2.0)
B12: B-BBEE Sector | C12: Generic / FMCG Distribution
A14: SHEET NAVIGATOR — Click sheet tabs to navigate | Blue cells = enter data | Green = auto-calculated
B15: Sheet | C15: Description | D15: Type
B16: ESG_Dashboard | C16: Master ESG summary — E·S·G scores, GHG tiles, KPIs | D16: ⚙️ AUTO
B17: E_Data | C17: Environmental raw data — 9 months actuals | D17: 🔵 DATA ENTRY
B18: S_Data | C18: Social — EE headcount, H&S, WSP/ATR, OFO codes | D18: 🔵 DATA ENTRY
B19: G_Data | C19: Governance — board, risk, POPIA, ethics | D19: 🔵 DATA ENTRY
B20: Fleet_Register | C20: 134-vehicle register — L/100km, tCO₂e, EV | D20: 🔵 DATA ENTRY
B21: Waste_Register | C21: Oricol, Oracle, Cority waste streams | D21: 🔵 DATA ENTRY
B22: Driver_Debrief | C22: Route completion %, excess km, fatigue flags | D22: 🔵 DATA ENTRY
B23: EE_Scorecard | C23: EEA2 scoring — Black%, female%, PWD% | D23: ⚙️ AUTO
B24: E_Scorecard | C24: Environmental score /100 — net-zero lens | D24: ⚙️ AUTO
B25: S_Scorecard | C25: Social score /100 — EE+WSP+H&S+Community | D25: ⚙️ AUTO
B26: G_Scorecard | C26: Governance score /100 — King V+IFRS+GARP | D26: ⚙️ AUTO
... B35: ISO_14083 | C35: Transport emissions per ISO 14083 / GLEC — trip register, intensity, customer alloc | D35: 🔵 DATA ENTRY
A36: COLOUR GUIDE: 🔵 Blue text = User input (enter data) | 🟢 Green bg = Auto-calculated | 🟡 Amber = Target/benchmark | 🔴 Red = Gap/below target | B36: B_BBEE_ESG | C36: B-BBEE Generic Code element mapping → status level + procurement recognition | D36: ⚙️ AUTO
B37: Materiality_Matrix | C37: Impact × Likelihood scoring with single/double materiality toggle | D37: ⚙️ AUTO
B38: Carbon_Tax | C38: Section 12L liability calc — Tier 1 + Tier 2 + mitigation scenarios | D38: ⚙️ AUTO
B39: Glossary | C39: Technical terms, definitions, source citations (98 entries) | D39: 📋 REFERENCE
B40: Assumptions | C40: Strategy toggles + thresholds + EFs (single source of truth) | D40: ⚙️ TOGGLES
A41: COLOUR GUIDE: 🔵 Blue text = User input (enter data) | 🟢 Green bg = Auto-calculated | 🟡 Amber = Target/benchmark | 🔴 Red = Gap/below target | 🟧 Orange bg = Strategy toggle
B42: Data_Status | C42: Live data tracker — every field with source, status, refresh date | D42: 📊 TRACKER

Sheet Assumptions
A1: ⚙ ASSUMPTIONS — Single source of truth for thresholds, weights, emission factors, targets
A2: Edit values in the BLUE cells to retune the toolkit. All scorecards reference this sheet — one edit cascades everywhere.
A3: 🔒 THIS INSTANCE IS CONFIGURED FOR SUPERGROUP — Transport / FMCG Distribution | Sector-locked deep build
A4: To deploy for a different sector (ICT, Financial Services, Mining, etc.) start from the Generic template — do not retrofit by changing the Sector toggle below. Each sector fork has bespoke depth (e.g. ISO 14083 for transport, task-based emissions for ICT, financed emissions for FinServ).
A6: BLOCK 0 — STRATEGY TOGGLES ★ PRIMARY CONTROLS — change these to retune the whole toolkit
A7: Setting | B7: Active value | C7: Options | D7: Code | E7: Effect on toolkit | F7: Cell ref
A8: Scoring stance | B8: Standard | C8: Lean / Standard / Strict | D8: STANCE | E8: Drives the banding floor (Lean 30% / Std 50% / Strict 70%) for partial credit on all quantitative indicators | F8: Assumptions!B6
A9: Banding floor (auto from stance) | B9: =IF(B8="Lean",0.3,IF(B8="Strict",0.7,0.5)) -> 0.5 | C9: 0.30 / 0.50 / 0.70 | D9: STANCE_FLR | E9: Below Actual/Target × this %, score = 0. Above, pro-rata. | F9: Assumptions!B7
A10: Sector | B10: Transport / FMCG Distribution | C10: See list → | D10: SECTOR | E10: 🔒 Sector-locked for this SuperGroup instance. The toolkit is configured around transport/distribution logic (ISO 14083, Fleet_Register, Driver_Debrief). To use for another sector, fork from the Generic template — do not change this dropdown. | F10: Assumptions!B8
A11: Primary reporting standard | B11: King V + IFRS S1/S2 | C11: SA / IFRS / GRI / ESRS / TCFD | D11: STD_PRIMARY | E11: Determines emphasis in dashboard, executive summary, and standards map | F11: Assumptions!B9
A12: Materiality basis | B12: Single (financial — IFRS) | C12: Single / Double / Dynamic | D12: MAT_BASIS | E12: Single: financial only (IFRS). Double: financial + impact (ESRS). Dynamic: both, evolving over time. | F12: Assumptions!B10
A13: Reporting currency | B13: ZAR | C13: See list → | D13: CCY | E13: Drives currency symbol on CSI, Carbon Tax, training spend, and procurement | F13: Assumptions!B11
A14: Currency symbol (auto)
A15: Carbon tax display | B15: Both (current + escalated) | C15: Current / Escalated / Both | D15: TAX_MODE | E15: Side-by-side liability view: Tier 1 (current) vs Tier 2 (escalated forward-looking) | F15: Assumptions!B13
A16: ★ How toggles work: change a value in column B → all scorecards and the dashboard recompute. The current scoring stance ("Standard") gives 50% banding floor; switch to "Lean" to use 30% (encourages early progress); switch to "Strict" for 70% (closer to B-BBEE binary).
A28: BLOCK 1 — EMISSION FACTORS (DEFRA 2024 · Eskom NERSA 2024 · GHG Protocol)
A29: Factor | B29: Value | C29: Unit | D29: Code | E29: Source / Reference | F29: Last Updated
A30: Diesel — road freight | B30: 2.68 | C30: kgCO₂e/L | D30: EF_DIESEL | E30: DEFRA 2024 — Mobile combustion, HGV diesel | F30: 2025-01-01
A31: Petrol — business vehicles | B31: 2.31 | C31: kgCO₂e/L | D31: EF_PETROL | E31: DEFRA 2024 — Passenger car petrol | F31: 2025-01-01
A32: LPG — forklifts | B32: 1.51 | C32: kgCO₂e/kg | D32: EF_LPG | E32: DEFRA 2024 — LPG combustion | F32: 2025-01-01
A33: Electricity — Eskom grid | B33: 0.82 | C33: kgCO₂e/kWh | D33: EF_ELEC | E33: Eskom NERSA 2024 — grid emission factor | F33: 2025-01-01
A34: Solar PV — onsite generation | B34: 0.025 | C34: kgCO₂e/kWh | D34: EF_SOLAR | E34: IEA / GHG Protocol — solar PV lifecycle | F34: 2025-01-01
A35: Municipal water | B35: 0.000344 | C35: tCO₂e/kL | D35: EF_WATER | E35: GHG Protocol — water supply & treatment | F35: 2025-01-01
A36: Waste to landfill | B36: 0.58 | C36: tCO₂e/tonne | D36: EF_LANDFILL | E36: DEFRA 2024 — landfilled commercial waste | F36: 2025-01-01
A37: Carbon Tax Tier 1 rate (ZAR) | B37: 236 | C37: ZAR/tCO₂e | D37: TAX_T1 | E37: SA Carbon Tax Act — Tier 1 rate 2025 (taxable above threshold) | F37: 2025-01-01
A38: Carbon Tax Tier 2 rate (ZAR) | B38: 640 | C38: ZAR/tCO₂e | D38: TAX_T2 | E38: SA Carbon Tax Act — projected escalation 2026 | F38: 2025-01-01
A39: Carbon Tax basic allowance | B39: 0.6 | C39: % exempt | D39: TAX_ALLOW | E39: SA Carbon Tax Act s7 — basic 60% tax-free allowance | F39: 2025-01-01
A41: BLOCK 2 — SCORING THRESHOLDS (used by E/S/G scorecards for banded scoring)
A42: Threshold | B42: Value | C42: Unit | D42: Code | E42: Used by / Applies to | F42: Rationale
A43: Scope 1+2 YoY reduction target | B43: 0.1 | C43: % | D43: THR_GHG_YOY | E43: E_Scorecard row 6 | F43: SBTi near-term: minimum 4.2% pa for 1.5°C; 10% stretch target
A44: Renewable electricity minimum | B44: 0.2 | C44: % | D44: THR_RE | E44: E_Scorecard row 13 | F44: RE100 entry threshold; SBTi Scope 2 lever
A45: Fleet L/100km tolerance over norm | B45: 1.05 | C45: multiplier | D45: THR_FUEL_TOL | E45: Fleet_Register, E_Scorecard row 15 | F45: 5% tolerance above OEM norm before flagged
A46: EV fleet % minimum (current) | B46: 0.05 | C46: % | D46: THR_EV_MIN | E46: E_Scorecard row 17 | F46: Min credible EV transition stake
A47: EV fleet % target 2030 | B47: 0.2 | C47: % | D47: THR_EV_2030 | E47: NetZero_Roadmap | F47: SBTi-aligned transport transition
A48: Waste diversion target | B48: 0.75 | C48: % | D48: THR_WASTE | E48: E_Scorecard row 19, Waste_Register | F48: ISO 14001 / NEMWA hierarchy alignment
A49: Waste diversion excellence | B49: 0.9 | C49: % | D49: THR_WASTE_X | E49: E_Scorecard row 19 | F49: Best-practice diversion (Oricol CPT benchmark)
A50: % Black employees target | B50: 0.6 | C50: % | D50: THR_BLACK | E50: EE_Scorecard, S_Scorecard row 5 | F50: EEA s27 demographic alignment; B-BBEE Mgt Control
A51: % Black female mgmt target | B51: 0.3 | C51: % | D51: THR_BFM | E51: EE_Scorecard, S_Scorecard row 6 | F51: B-BBEE Mgt Control sub-target
A52: % Persons with Disabilities target | B52: 0.02 | C52: % | D52: THR_PWD | E52: EE_Scorecard, S_Scorecard row 8 | F52: EEA s6 / Code of Good Practice on PWD
A53: Training hours per employee target | B53: 40 | C53: hours | D53: THR_TRAIN_HR | E53: S_Scorecard row 14 | F53: GRI 404-1; B-BBEE SD typical benchmark
...

Sheet Audit_Log
A1: 📋 AUDIT LOG — Version control · change history · sign-offs
A2: Log every formula change, threshold update, scope extension. Critical for ISAE 3000 / external assurance trail.
A4: VERSION HISTORY
A5: Version | B5: Date | C5: Author | D5: Section | E5: Change Description | F5: Signed off by
A6: v1.0 | B6: 2025-09-01 | C6: Khethiwe Nkuna | D6: All sheets | E6: Initial toolkit build for SG Consumer FY25/26 baseline | F6: C Myezwa
A7: v1.1 | B7: 2025-11-15 | C7: Okiru Consulting | D7: E_Data | E7: Added SCOPE 1B–1D (generator, LPG, business cars) | F7: Z Mnanzana
A8: v1.2 | B8: 2026-01-10 | C8: Okiru Consulting | D8: Fleet_Register | E8: Added 134-vehicle register with L/100km norms by class | F8: Z Mnanzana
A9: v1.3 | B9: 2026-02-22 | C9: Okiru Consulting | D9: King5_Scorecard | E9: Migrated to Apply & Explain methodology — all 17 principles | F9: C Myezwa
A10: v1.4 | B10: 2026-04-01 | C10: Okiru Consulting | D10: NetZero_Roadmap | E10: Added SBTi CNZS 2.0 pathway and OER tier mapping | F10: C Myezwa
A11: v1.5 | B11: 2026-05-14 | C11: Okiru Consulting | D11: Engine rebuild | E11: Full scoring engine rebuild: Assumptions sheet, banded scoring, audit columns, dashboard charts, Materiality_Matrix, B_BBEE_ESG, Carbon_Tax. Productised template + SG Consumer live instance. | F11: [pending]
A12: v1.6 | B12: 2026-05-25 | C12: Okiru Consulting | D12: G_Data, King5_Scorecard, IFRS_S1_S2, GARP_GRAP, ISO_Tracker, SAQ_Supplier | E12: Populated governance evidence from SG Consumer policy stack (Code of Ethics, CSI/SED, EE & Workplace Diversity, Supplier Code — all Rev 2 dated 30 Jan 2023) + SG Consumer POPI Act Consent (Jan 2026). Updates: G_Data Y/N flags with traceable source notes; King V Apply/Explain status for 17 principles; IFRS S1/S2 Partially Disclosed flags where policy commitments exist without operational evidence; GARP_GRAP control evidence column populated; ISO 14001/45001/26000/27001 clause-level status. No formulas changed. | F12: [pending C Myezwa]
A13: 2026-05-27 | B13: v1.7 | C13: SG Consumer data load — Coba 27 May 2026 submission | D13: Payroll R10,331,940.87; FTE 426; Board comp (Group, 7 directors); CSI/SED beneficiaries (10 programmes, R45k budget); H&S incidents (19 from SHE register); Be Heard hotline confirmed | E13: Okiru Consulting | F13: Outstanding: EEA2 race/gender split for 426 FTE; Scope 3 business travel km; CSI per-project spend split; POPIA case data (HO)
A14: FORMULA CHANGE LOG — v1.5 engine rebuild (target counts; populated in Step 2)
A15: Sheet | B15: Cells touched | C15: From | D15: To | E15: Rationale | F15: Tested
A16: E_Scorecard | B16: C6:C29 | C16: 17 hardcoded zeros | D16: Banded scoring referencing E_Data + Assumptions | E16: Engine rebuild — every score must trace to source | F16: pending
A17: S_Scorecard | B17: C6:C27 | C17: 16 hardcoded zeros | D17: Banded scoring referencing S_Data + Assumptions | E17: Engine rebuild | F17: pending
A18: G_Scorecard | B18: C6:C25 | C18: 13 hardcoded zeros | D18: Banded scoring referencing G_Data + Assumptions | E18: Engine rebuild | F18: pending
A19: G_Data | B19: F5:F24 | C19: All zeros (no logic) | D19: Banded Y/N + count scoring | E19: Wire governance data to G_Scorecard | F19: pending
A20: GARP_GRAP | B20: F:H | C20: No formulas | D20: Severity × Likelihood scoring; control modifier | E20: Materiality matrix feed | F20: pending
A21: ESG_Dashboard | B21: B25,B27:B29,B31 | C21: Hardcoded =0 | D21: Live pulls from data + scorecard sheets | E21: Make KPI tiles real | F21: pending
A22: Standards_Map | B22: I column | C22: References still valid | D22: Add Audit_Log + Assumptions cross-refs | E22: Complete the map | F22: pending
A25: SIGN-OFF — required before publishing to client
A26: Role | B26: Name | C26: Date | D26: Signature | E26: Scope of approval
A27: Senior ESG Consultant | B27: Khethiwe Nkuna | E27: Technical accuracy of E/S/G scoring
A28: Managing Director | B28: Chengetai Myezwa | E28: Client suitability and risk
A29: Senior B-BBEE Consultant | B29: Zoleka Mnanzana | E29: B-BBEE Generic Code element alignment
A30: Client representative | B30: [Client name] | E30: Acceptance and data accuracy

Sheet ESG_Dashboard
A1: 🌱 ESG INTELLIGENCE DASHBOARD — SG Consumer | FY 2025/26 | Powered by Okiru Consulting
A2: Net-Zero · King V · IFRS S1/S2 · GARP/GRAP · ISO 14001/45001/27001 · Employment Equity · WSP/ATR
A4: ESG PILLAR SCORES | L4: EXECUTIVE SUMMARY — Board view
A5: Pillar | B5: Score | C5: Max | D5: % Score | E5: Rating | F5: Key Gap | G5: Net-Zero Link | H5: Standards | I5: Target FY26 | J5: Status | L5: Overall ESG Score | M5: =TEXT(D9,"0.0%") -> 44.6%
A6: 🟢 Environmental (E) | B6: =E_Scorecard!D30 -> 36 | C6: 108 | D6: =IFERROR(B6/C6,0) -> 0.33333333 | E6: =IF(D6>=Assumptions!$B$62,"★★★ Excellent",IF(D6>=Assumptions!$B$63,"★★ Good",IF(D6>=Assumptions!$B$64,"★ Adequate","⚠ Attention"))) -> ⚠ Attention | F6: GHG Scope 1+2+3 | G6: Fleet diesel dominant | H6: IFRS S2/GRI 305/ISO14001 | I6: ≥75/100 | J6: =IF(D6>=Assumptions!$B$65,"✓ On Track","⚠ Behind") -> ⚠ Behind | L6: Rating | M6: =IF(D9>=Assumptions!$B$62,"★★★ Excellent",IF(D9>=Assumptions!$B$63,"★★ Good",IF(D9>=Assumptions!$B$64,"★ Adequate","⚠ Needs Attention"))) -> ⚠ Needs Attention
A7: 🔵 Social (S) | B7: =S_Scorecard!D28 -> 33 | C7: 100 | D7: =IFERROR(B7/C7,0) -> 0.33 | E7: =IF(D7>=Assumptions!$B$62,"★★★ Excellent",IF(D7>=Assumptions!$B$63,"★★ Good",IF(D7>=Assumptions!$B$64,"★ Adequate","⚠ Attention"))) -> ⚠ Attention | F7: EE targets | G7: EE + WSP compliance | H7: EEA/GRI 405/ISO45001 | I7: ≥75/100 | J7: =IF(D7>=Assumptions!$B$65,"✓ On Track","⚠ Behind") -> ⚠ Behind | L7: Strongest pillar | M7: =INDEX(A6:A8,MATCH(MAX(D6:D8),D6:D8,0)) -> 🟣 Governance (G)
A8: 🟣 Governance (G) | B8: =G_Scorecard!D26 -> 64.852941 | C8: 100 | D8: =IFERROR(B8/C8,0) -> 0.64852941 | E8: =IF(D8>=Assumptions!$B$62,"★★★ Excellent",IF(D8>=Assumptions!$B$63,"★★ Good",IF(D8>=Assumptions!$B$64,"★ Adequate","⚠ Attention"))) -> ★ Adequate | F8: King V full adoption | G8: IFRS S2 + King V P10 | H8: King V/IFRS S1-S2/POPIA | I8: ≥75/100 | J8: =IF(D8>=Assumptions!$B$65,"✓ On Track","⚠ Behind") -> ⚠ Behind | L8: Weakest pillar | M8: =INDEX(A6:A8,MATCH(MIN(D6:D8),D6:D8,0)) -> 🔵 Social (S)
A9: OVERALL ESG SCORE | D9: =IFERROR((E_Scorecard!D30/100+S_Scorecard!D28/100+G_Scorecard!D26/100)/3,0) -> 0.44617647 | L9: Material risks | M9: =GARP_GRAP!C28&" of "&GARP_GRAP!C27&" risks logged" -> 12 of 18 risks logged
L10: King V status | M10: =King5_Scorecard!E21&"/170 ("&TEXT(King5_Scorecard!E22,"0.0%")&")" -> 135/170 (79.4%)
A11: GHG EMISSIONS SUMMARY (tCO₂e) | 9 months actuals Jul-25 to Mar-26
A12: Scope | B12: Jul-25 | C12: Aug-25 | D12: Sep-25 | E12: Oct-25 | F12: Nov-25 | G12: Dec-25 | H12: Jan-26 | I12: Feb-26 | J12: Mar-26 | K12: YTD Total | L12: Annualised | M12: YoY Target | N12: Status
A13: Scope 1 — Fleet Diesel | B13: =IFERROR(E_Data!C75,0) -> 79354.07 | C13: =IFERROR(E_Data!D75,0) -> 68178.89 | D13: =IFERROR(E_Data!E75,0) -> 65076.46 | E13: =IFERROR(E_Data!F75,0) -> 73386.91 | F13: =IFERROR(E_Data!G75,0) -> 67294.64 | G13: =IFERROR(E_Data!H75,0) -> 57589.35 | H13: =IFERROR(E_Data!I75,0) -> 48740.43 | I13: =IFERROR(E_Data!J75,0) -> 63979.73 | J13: =IFERROR(E_Data!K75,0) -> 65865.05 | K13: =IFERROR(SUM(B13:J13),0) -> 589465.53 | L13: =IFERROR(K13*Assumptions!$B$112,0) -> 785954.04 | M13: — baseline year — | N13: ○ Baseline
A14: Scope 1 — Generator | B14: =IFERROR(E_Data!C76,0) -> 1289.14 | C14: =IFERROR(E_Data!D76,0) -> 0 | D14: =IFERROR(E_Data!E76,0) -> 0 | E14: =IFERROR(E_Data!F76,0) -> 0 | F14: =IFERROR(E_Data!G76,0) -> 0 | G14: =IFERROR(E_Data!H76,0) -> 295 | H14: =IFERROR(E_Data!I76,0) -> 0 | I14: =IFERROR(E_Data!J76,0) -> 0 | J14: =IFERROR(E_Data!K76,0) -> 597 | K14: =IFERROR(SUM(B14:J14),0) -> 2181.14 | L14: =IFERROR(K14*Assumptions!$B$112,0) -> 2908.1867 | M14: — baseline year — | N14: ○ Baseline
A15: Scope 1 — LPG Forklifts | B15: =IFERROR(E_Data!C77,0) -> 0 | C15: =IFERROR(E_Data!D77,0) -> 570 | D15: =IFERROR(E_Data!E77,0) -> 190 | E15: =IFERROR(E_Data!F77,0) -> 190 | F15: =IFERROR(E_Data!G77,0) -> 380 | G15: =IFERROR(E_Data!H77,0) -> 570 | H15: =IFERROR(E_Data!I77,0) -> 380 | I15: =IFERROR(E_Data!J77,0) -> 0 | J15: =IFERROR(E_Data!K77,0) -> 0 | K15: =IFERROR(SUM(B15:J15),0) -> 2280 | L15: =IFERROR(K15*Assumptions!$B$112,0) -> 3040 | M15: — baseline year — | N15: ○ Baseline
A16: Scope 2 — Electricity (grid) | B16: =IFERROR(E_Data!C82,0) -> 288638.88 | C16: =IFERROR(E_Data!D82,0) -> 304665.02 | D16: =IFERROR(E_Data!E82,0) -> 294858.49 | E16: =IFERROR(E_Data!F82,0) -> 263387.94 | F16: =IFERROR(E_Data!G82,0) -> 255634.03 | G16: =IFERROR(E_Data!H82,0) -> 290165.23 | H16: =IFERROR(E_Data!I82,0) -> 261690.52 | I16: =IFERROR(E_Data!J82,0) -> 315712.51 | J16: =IFERROR(E_Data!K82,0) -> 314825.82 | K16: =IFERROR(SUM(B16:J16),0) -> 2589578.4 | L16: =IFERROR(K16*Assumptions!$B$112,0) -> 3452771.3 | M16: — baseline year — | N16: ○ Baseline
A17: Scope 3 — Water | B17: =IFERROR(E_Data!C83,0) -> 409.41 | C17: =IFERROR(E_Data!D83,0) -> 391.39 | D17: =IFERROR(E_Data!E83,0) -> 380.72 | E17: =IFERROR(E_Data!F83,0) -> 534.81 | F17: =IFERROR(E_Data!G83,0) -> 476.36 | G17: =IFERROR(E_Data!H83,0) -> 499.53 | H17: =IFERROR(E_Data!I83,0) -> 533.01 | I17: =IFERROR(E_Data!J83,0) -> 560.94 | J17: =IFERROR(E_Data!K83,0) -> 570.24 | K17: =IFERROR(SUM(B17:J17),0) -> 4356.41 | L17: =IFERROR(K17*Assumptions!$B$112,0) -> 5808.5467 | M17: — baseline year — | N17: ○ Baseline
A18: TOTAL GHG (Scope 1+2+3) | B18: =SUM(B13:B17) -> 369691.5 | C18: =SUM(C13:C17) -> 373805.3 | D18: =SUM(D13:D17) -> 360505.67 | E18: =SUM(E13:E17) -> 337499.66 | F18: =SUM(F13:F17) -> 323785.03 | G18: =SUM(G13:G17) -> 349119.11 | H18: =SUM(H13:H17) -> 311343.96 | I18: =SUM(I13:I17) -> 380253.18 | ... K18: =SUM(K13:K17) -> 3187861.5 | L18: =K18*Assumptions!$B$112 -> 4250482 | M18: — baseline year — | N18: ○ Baseline
A19: KEY NET-ZERO & ESG KPIs — YTD FY2025/26
A20: KPI | B20: Value | C20: Benchmark | D20: Source
A21: Total fleet diesel (litres YTD) | B21: =E_Data!L19 -> 589465.53 | C21: <600,000 L target | D21: Fleet_Register
A22: Total fleet tCO₂e Scope 1 | B22: =IFERROR(E_Data!L79,0) -> 594980.49 | C22: <1,600 tCO₂e | D22: E_Data
A23: Total electricity kWh YTD | B23: =E_Data!L46 -> 2589578.4 | C23: Monitor vs prior year | D23: Utility_Bills
A24: Total electricity tCO₂e Scope 2 | B24: =IFERROR(E_Data!L82,0) -> 2589578.4 | C24: Target: reduce 10% YoY | D24: E_Data
A25: Fleet avg L/100km vs norm | B25: =IFERROR(AVERAGEIFS(Fleet_Register!K4:K19,Fleet_Register!K4:K19,">0"),"No data") -> No data | C25: ≤ vehicle norm | D25: Fleet_Register
A26: Oricol CPT waste diversion % | B26: =Waste_Register!B16 -> 0.911 | C26: ≥90% — Target Met ✓ | D26: Waste_Register
A27: EE: % Black employees | B27: =EE_Scorecard!B5 -> 0 | C27: ≥60% | D27: EE_Scorecard
A28: WSP submitted to SETA | B28: =S_Data!B45 -> 0 | C28: Yes — Required | D28: S_Data
A29: LTIFR YTD | B29: =IFERROR(S_Data!G35,"No data") -> Awaiting hours worked | C29: <2.0 | D29: S_Data
A30: King V score | B30: =King5_Scorecard!E21 -> 135 | C30: ≥100/170 | D30: King5_Scorecard
A31: IFRS S1/S2 disclosures | B31: =IFERROR(COUNTIF(IFRS_S1_S2!D4:D40,"Yes")/MAX(1,COUNTA(IFRS_S1_S2!A4:A40)-COUNTBLANK(IFRS_S1_S2!A4:A40)),0) -> 0 | C31: ≥80% disclosed | D31: IFRS_S1_S2
A32: ISO 14001 certification status | C32: Certified (target) | D32: ISO_Tracker
A75: Materiality data (auto)
A76: Risk | B76: Severity | C76: Likelihood | D76: Risk Score
A77: =GARP_GRAP!B5 -> Climate Physical Risk | B77: =IF(GARP_GRAP!E5="High",5,IF(GARP_GRAP!E5="Medium",3,IF(GARP_GRAP!E5="Low",1,IF(GARP_GRAP!E5="Req",4,0)))) -> 5 | C77: =GARP_GRAP!I5 -> 4 | D77: =GARP_GRAP!J5 -> 20
A78: =GARP_GRAP!B6 -> Climate Transition Risk | B78: =IF(GARP_GRAP!E6="High",5,IF(GARP_GRAP!E6="Medium",3,IF(GARP_GRAP!E6="Low",1,IF(GARP_GRAP!E6="Req",4,0)))) -> 5 | C78: =GARP_GRAP!I6 -> 5 | D78: =GARP_GRAP!J6 -> 25
A79: =GARP_GRAP!B7 -> Operational Risk — Fleet | B79: =IF(GARP_GRAP!E7="High",5,IF(GARP_GRAP!E7="Medium",3,IF(GARP_GRAP!E7="Low",1,IF(GARP_GRAP!E7="Req",4,0)))) -> 5 | C79: =GARP_GRAP!I7 -> 5 | D79: =GARP_GRAP!J7 -> 25
A80: =GARP_GRAP!B8 -> Regulatory Risk — EE Act | B80: =IF(GARP_GRAP!E8="High",5,IF(GARP_GRAP!E8="Medium",3,IF(GARP_GRAP!E8="Low",1,IF(GARP_GRAP!E8="Req",4,0)))) -> 3 | C80: =GARP_GRAP!I8 -> 3 | D80: =GARP_GRAP!J8 -> 9
A81: =GARP_GRAP!B9 -> Regulatory Risk — POPIA | B81: =IF(GARP_GRAP!E9="High",5,IF(GARP_GRAP!E9="Medium",3,IF(GARP_GRAP!E9="Low",1,IF(GARP_GRAP!E9="Req",4,0)))) -> 3 | C81: =GARP_GRAP!I9 -> 3 | D81: =GARP_GRAP!J9 -> 9
A82: =GARP_GRAP!B10 -> Financial Risk — SDL/WSP | B82: =IF(GARP_GRAP!E10="High",5,IF(GARP_GRAP!E10="Medium",3,IF(GARP_GRAP!E10="Low",1,IF(GARP_GRAP!E10="Req",4,0)))) -> 3 | C82: =GARP_GRAP!I10 -> 3 | D82: =GARP_GRAP!J10 -> 9
A83: =GARP_GRAP!B11 -> Reputational Risk — ESG | B83: =IF(GARP_GRAP!E11="High",5,IF(GARP_GRAP!E11="Medium",3,IF(GARP_GRAP!E11="Low",1,IF(GARP_GRAP!E11="Req",4,0)))) -> 3 | C83: =GARP_GRAP!I11 -> 3 | D83: =GARP_GRAP!J11 -> 9
...

Sheet E_Data
A1: E_DATA — ENVIRONMENTAL RAW DATA | SG Consumer | FY 2025/26
A3: EMISSION FACTORS (DEFRA 2024 / Eskom NERSA 2024) — edit only if factors updated
A4: EF_DIESEL | B4: 2.68 | C4: kgCO₂e/L | D4: Road freight diesel (DEFRA 2024)
A5: EF_PETROL | B5: 2.31 | C5: kgCO₂e/L | D5: Business car petrol
A6: EF_LPG | B6: 1.51 | C6: kgCO₂e/kg | D6: LPG forklifts (DBN warehouse)
A7: EF_ELEC | B7: 0.82 | C7: kgCO₂e/kWh | D7: Eskom grid — NERSA 2024
A8: EF_SOLAR | B8: 0.025 | C8: kgCO₂e/kWh | D8: Solar PV (onsite generation)
A9: EF_WATER | B9: 0.000344 | C9: tCO₂e/kL | D9: Municipal water (GHG Protocol)
A10: EF_LANDFILL | B10: 0.58 | C10: tCO₂e/tonne | D10: Waste to landfill
A12: SCOPE 1A — ROAD FREIGHT DIESEL (Fleet litres per depot) [Source: Mariette Dashboard fuel consumption sheet]
A13: Depot/Source | B13: Unit | C13: Jul-25 | D13: Aug-25 | E13: Sep-25 | F13: Oct-25 | G13: Nov-25 | H13: Dec-25 | I13: Jan-26 | J13: Feb-26 | K13: Mar-26 | L13: YTD Total | M13: tCO₂e YTD | N13: Source File
A14: SG Consumer – BLOEM | B14: litres | C14: 17639.52 | D14: 12721.25 | E14: 5877.41 | F14: 6836 | G14: 5002 | H14: 6977 | I14: 4713 | J14: 6995.19 | K14: 5922 | L14: =SUM(C14:K14) -> 72683.37 | M14: =L14*E_Data!$B$4/1000 -> 194.79143 | N14: Mariette/STATS/DASHBOARD 2025-2026
A15: SG Consumer – CPT | B15: litres | C15: 6789 | D15: 6039 | E15: 5927 | F15: 6936 | G15: 5857 | H15: 6518 | I15: 4171.01 | J15: 3146 | K15: 6417 | L15: =SUM(C15:K15) -> 51800.01 | M15: =L15*E_Data!$B$4/1000 -> 138.82403 | N15: Mariette/STATS/DASHBOARD 2025-2026
A16: SG Consumer – DBN | B16: litres | C16: 17716.57 | D16: 14729.31 | E16: 16273.31 | F16: 18434 | G16: 18357.36 | H16: 18828 | I16: 13750.41 | J16: 19177.8 | K16: 19512.38 | L16: =SUM(C16:K16) -> 156779.14 | M16: =L16*E_Data!$B$4/1000 -> 420.1681 | N16: Mariette/STATS/DASHBOARD 2025-2026
A17: SG Consumer – ISANDO | B17: litres | C17: 35757.98 | D17: 33349.25 | E17: 35581.74 | F17: 39804.91 | G17: 36773.79 | H17: 23998.48 | I17: 24838.14 | J17: 33208.74 | K17: 32745.8 | L17: =SUM(C17:K17) -> 296058.83 | M17: =L17*E_Data!$B$4/1000 -> 793.43766 | N17: Mariette/STATS/DASHBOARD 2025-2026
A18: SG Consumer – PE | B18: litres | C18: 1451 | D18: 1340.08 | E18: 1417 | F18: 1376 | G18: 1304.49 | H18: 1267.87 | I18: 1267.87 | J18: 1452 | K18: 1267.87 | L18: =SUM(C18:K18) -> 12144.18 | M18: =L18*E_Data!$B$4/1000 -> 32.546402 | N18: Mariette/STATS/DASHBOARD 2025-2026
A19: TOTAL FLEET DIESEL | C19: =C14+C15+C16+C17+C18 -> 79354.07 | D19: =D14+D15+D16+D17+D18 -> 68178.89 | E19: =E14+E15+E16+E17+E18 -> 65076.46 | F19: =F14+F15+F16+F17+F18 -> 73386.91 | G19: =G14+G15+G16+G17+G18 -> 67294.64 | H19: =H14+H15+H16+H17+H18 -> 57589.35 | I19: =I14+I15+I16+I17+I18 -> 48740.43 | J19: =J14+J15+J16+J17+J18 -> 63979.73 | ... L19: =L14+L15+L16+L17+L18 -> 589465.53 | M19: =L19*E_Data!$B$4/1000 -> 1579.7676
A21: SCOPE 1B — GENERATOR DIESEL (litres per depot) [Source: Mariette Dashboard / Bowser Recon]
A22: Depot | B22: Unit | C22: Jul-25 | D22: Aug-25 | E22: Sep-25 | F22: Oct-25 | G22: Nov-25 | H22: Dec-25 | I22: Jan-26 | J22: Feb-26 | K22: Mar-26 | L22: YTD Total | M22: tCO₂e YTD
A23: Generator – BLOEM | B23: litres | C23: 650 | D23: 0 | E23: 0 | F23: 0 | G23: 0 | H23: 0 | I23: 0 | J23: 0 | K23: 597 | L23: =SUM(C23:K23) -> 1247 | M23: =L23*E_Data!$B$4/1000 -> 3.34196
A24: Generator – CPT | B24: litres | C24: 0 | D24: 0 | E24: 0 | F24: 0 | G24: 0 | H24: 0 | I24: 0 | J24: 0 | K24: 0 | L24: =SUM(C24:K24) -> 0 | M24: =L24*E_Data!$B$4/1000 -> 0
A25: Generator – DBN | B25: litres | C25: 639.14 | D25: 0 | E25: 0 | F25: 0 | G25: 0 | H25: 0 | I25: 0 | J25: 0 | K25: 0 | L25: =SUM(C25:K25) -> 639.14 | M25: =L25*E_Data!$B$4/1000 -> 1.7128952
A26: Generator – ISANDO | B26: litres | C26: 0 | D26: 0 | E26: 0 | F26: 0 | G26: 0 | H26: 0 | I26: 0 | J26: 0 | K26: 0 | L26: =SUM(C26:K26) -> 0 | M26: =L26*E_Data!$B$4/1000 -> 0
A27: Generator – PE | B27: litres | C27: 0 | D27: 0 | E27: 0 | F27: 0 | G27: 0 | H27: 295 | I27: 0 | J27: 0 | K27: 0 | L27: =SUM(C27:K27) -> 295 | M27: =L27*E_Data!$B$4/1000 -> 0.7906
A28: TOTAL GENERATOR | C28: =C23+C24+C25+C26+C27 -> 1289.14 | D28: =D23+D24+D25+D26+D27 -> 0 | E28: =E23+E24+E25+E26+E27 -> 0 | F28: =F23+F24+F25+F26+F27 -> 0 | G28: =G23+G24+G25+G26+G27 -> 0 | H28: =H23+H24+H25+H26+H27 -> 295 | I28: =I23+I24+I25+I26+I27 -> 0 | J28: =J23+J24+J25+J26+J27 -> 0 | ... L28: =L23+L24+L25+L26+L27 -> 2181.14 | M28: =L28*E_Data!$B$4/1000 -> 5.8454552
A30: SCOPE 1C — LPG FORKLIFTS (kg per depot) [Source: Mariette Dashboard gas-forklifts sheet]
A31: Depot/Unit | B31: Unit | C31: Jul-25 | D31: Aug-25 | E31: Sep-25 | F31: Oct-25 | G31: Nov-25 | H31: Dec-25 | I31: Jan-26 | J31: Feb-26 | K31: Mar-26 | L31: YTD kg | M31: tCO₂e YTD
A32: LPG Forklifts – DBN | B32: kg | C32: 0 | D32: 570 | E32: 190 | F32: 190 | G32: 380 | H32: 570 | I32: 380 | J32: 0 | K32: 0 | L32: =SUM(C32:K32) -> 2280 | M32: =L32*E_Data!$B$6/1000 -> 3.4428
A33: NOTE: BLOEM, CPT, ISANDO, PE use electric/lithium-battery forklifts — no LPG emissions. Sanulac data confirms depot-level forklift types.
A35: SCOPE 1D — ROAD BUSINESS (Solly's car, ISANDO) [Source: Mariette Dashboard fuel consumption sheet]
A36: Source | B36: Unit | C36: Jul-25 | D36: Aug-25 | E36: Sep-25 | F36: Oct-25 | G36: Nov-25 | H36: Dec-25 | I36: Jan-26 | J36: Feb-26 | K36: Mar-26 | L36: YTD | M36: tCO₂e
A37: Solly's Car – ISANDO | B37: litres | C37: 139.81 | D37: 142.25 | E37: 93.22 | F37: 109.49 | G37: 143.81 | H37: 74.68 | I37: 109.59 | J37: 98 | K37: 142.97 | L37: =SUM(C37:K37) -> 1053.82 | M37: =L37*E_Data!$B$5/1000 -> 2.4343242
A39: SCOPE 2 — ELECTRICITY (kWh per depot/landlord) [Source: Mariette Utility Bills 2025-26]
A40: Depot / Landlord | B40: Unit | C40: Jul-25 | D40: Aug-25 | E40: Sep-25 | F40: Oct-25 | G40: Nov-25 | H40: Dec-25 | I40: Jan-26 | J40: Feb-26 | K40: Mar-26 | L40: YTD kWh | M40: tCO₂e YTD | N40: Landlord
A41: SG Consumer – BLOEM | B41: kWh | C41: 20495 | D41: 26100 | E41: 26118 | F41: 13295 | G41: 12343 | H41: 12343 | I41: 12343 | J41: 8126 | K41: 8131 | L41: =SUM(C41:K41) -> 139294 | M41: =L41*E_Data!$B$7/1000 -> 114.22108 | N41: KAVOD
A42: SG Consumer – CPT | B42: kWh | C42: 35751.88 | D42: 37731.52 | E42: 37625.99 | F42: 31990.94 | G42: 32243.53 | H42: 32243.53 | I42: 32524.52 | J42: 33991.51 | K42: 39024.17 | L42: =SUM(C42:K42) -> 313127.59 | M42: =L42*E_Data!$B$7/1000 -> 256.76462 | N42: SPEAR
A43: SG Consumer – DBN | B43: kWh | C43: 73374 | D43: 74374 | E43: 74374 | F43: 67241 | G43: 68442 | H43: 65167 | I43: 51805 | J43: 119050 | K43: 75298 | L43: =SUM(C43:K43) -> 669125 | M43: =L43*E_Data!$B$7/1000 -> 548.6825 | N43: EXCELLERATE
A44: SG Consumer – ISANDO | B44: kWh | C44: 147015 | D44: 152733 | E44: 143245 | F44: 137371 | G44: 126447 | H44: 165869 | I44: 149823 | J44: 138674 | K44: 137607 | L44: =SUM(C44:K44) -> 1298784 | M44: =L44*E_Data!$B$7/1000 -> 1065.0029 | N44: LEXSHELL 280 INVESTMENTS
A45: SG Consumer – PE | B45: kWh | C45: 12003 | D45: 13726.5 | E45: 13495.5 | F45: 13490 | G45: 16158.5 | H45: 14542.7 | I45: 15195 | J45: 15871 | K45: 54765.65 | L45: =SUM(C45:K45) -> 169247.85 | M45: =L45*E_Data!$B$7/1000 -> 138.78324 | N45: CLEMLEN INVESTMENTS NO 10
A46: TOTAL ELECTRICITY | C46: =C41+C42+C43+C44+C45 -> 288638.88 | D46: =D41+D42+D43+D44+D45 -> 304665.02 | E46: =E41+E42+E43+E44+E45 -> 294858.49 | F46: =F41+F42+F43+F44+F45 -> 263387.94 | G46: =G41+G42+G43+G44+G45 -> 255634.03 | H46: =H41+H42+H43+H44+H45 -> 290165.23 | I46: =I41+I42+I43+I44+I45 -> 261690.52 | J46: =J41+J42+J43+J44+J45 -> 315712.51 | ... M46: =M41+M42+M43+M44+M45 -> 2123.4543
...

Sheet Fleet_Register
A1: FLEET REGISTER — Per-Vehicle CO₂ | L/100km | EV Mix | Service Status [Source: Updated Fleet List Feb 2026]
A3: Reg | B3: Depot | C3: Model/Category | D3: GVM (kg) | E3: Tare (kg) | F3: Carry (kg) | G3: Fuel Cap (L) | H3: Tracking | I3: Monthly km | J3: Monthly Litres | K3: L/100km Actual | L3: L/100km Norm | M3: Monthly tCO₂e | N3: Service Status | O3: Licence Expiry
A4: JR45DZGP | B4: SGTSPFMCG | C4: 11-Seater Bus | D4: 3445 | E4: 2395 | F4: 1050 | G4: 100 | H4: I-CAM | I4: 0 | J4: 0 | K4: =IFERROR(J4/I4*100,0) -> 0 | L4: 30 | M4: =J4*E_Data!$B$4/1000 -> 0 | N4: =IF(L4=0,"N/A",IF(K4=0,"No data",IF(K4<=L4*1.05,"✓ Good",IF(K4<=L4*1.15,"⚠ Alert","🔴 High")))) -> No data
A5: KY75THGP | B5: SGTSPFMCG | C5: HINO 1627 8T Fridge | D5: 16000 | E5: 8180 | F5: 7820 | G5: 390 | H5: I-CAM | I5: 0 | J5: 0 | K5: =IFERROR(J5/I5*100,0) -> 0 | L5: 26.5 | M5: =J5*E_Data!$B$4/1000 -> 0 | N5: =IF(L5=0,"N/A",IF(K5=0,"No data",IF(K5<=L5*1.05,"✓ Good",IF(K5<=L5*1.15,"⚠ Alert","🔴 High")))) -> No data
A6: KY82RLGP | B6: SGTBLOEM | C6: HINO 614 2.5T | D6: 5500 | E6: 3220 | F6: 2280 | G6: 100 | H6: I-CAM | I6: 0 | J6: 0 | K6: =IFERROR(J6/I6*100,0) -> 0 | L6: 18 | M6: =J6*E_Data!$B$4/1000 -> 0 | N6: =IF(L6=0,"N/A",IF(K6=0,"No data",IF(K6<=L6*1.05,"✓ Good",IF(K6<=L6*1.15,"⚠ Alert","🔴 High")))) -> No data
A7: KY98LTGP | B7: SGTSPFMCG | C7: HINO 816 4T Curtain | D7: 8000 | E7: 4180 | F7: 3820 | G7: 200 | H7: I-CAM | I7: 0 | J7: 0 | K7: =IFERROR(J7/I7*100,0) -> 0 | L7: 22 | M7: =J7*E_Data!$B$4/1000 -> 0 | N7: =IF(L7=0,"N/A",IF(K7=0,"No data",IF(K7<=L7*1.05,"✓ Good",IF(K7<=L7*1.15,"⚠ Alert","🔴 High")))) -> No data
A8: KY98MRGP | B8: SGTSPFMCG | C8: HINO 816 4T Curtain | D8: 8000 | E8: 4180 | F8: 3820 | G8: 200 | H8: I-CAM | I8: 0 | J8: 0 | K8: =IFERROR(J8/I8*100,0) -> 0 | L8: 22 | M8: =J8*E_Data!$B$4/1000 -> 0 | N8: =IF(L8=0,"N/A",IF(K8=0,"No data",IF(K8<=L8*1.05,"✓ Good",IF(K8<=L8*1.15,"⚠ Alert","🔴 High")))) -> No data
A9: KZ00LCGP | B9: SGTBLOEM | C9: HINO 500 1627 8T Fridge | D9: 16000 | E9: 8180 | F9: 7820 | G9: 390 | H9: I-CAM | I9: 0 | J9: 0 | K9: =IFERROR(J9/I9*100,0) -> 0 | L9: 26.5 | M9: =J9*E_Data!$B$4/1000 -> 0 | N9: =IF(L9=0,"N/A",IF(K9=0,"No data",IF(K9<=L9*1.05,"✓ Good",IF(K9<=L9*1.15,"⚠ Alert","🔴 High")))) -> No data
A10: KZ00LHGP | B10: SGTBLOEM | C10: HINO 500 1627 8T Fridge | D10: 16000 | E10: 8180 | F10: 7820 | G10: 390 | H10: I-CAM | I10: 0 | J10: 0 | K10: =IFERROR(J10/I10*100,0) -> 0 | L10: 26.5 | M10: =J10*E_Data!$B$4/1000 -> 0 | N10: =IF(L10=0,"N/A",IF(K10=0,"No data",IF(K10<=L10*1.05,"✓ Good",IF(K10<=L10*1.15,"⚠ Alert","🔴 High")))) -> No data
A11: KZ97BKGP | B11: SGTSPFMCG | C11: HINO 1627 8T Fridge | D11: 16000 | E11: 8180 | F11: 7820 | G11: 390 | H11: I-CAM | I11: 0 | J11: 0 | K11: =IFERROR(J11/I11*100,0) -> 0 | L11: 26.5 | M11: =J11*E_Data!$B$4/1000 -> 0 | N11: =IF(L11=0,"N/A",IF(K11=0,"No data",IF(K11<=L11*1.05,"✓ Good",IF(K11<=L11*1.15,"⚠ Alert","🔴 High")))) -> No data
A12: LB45BMGP | B12: SGTBLOEM | C12: HINO 1627 16T Fridge | D12: 25380 | E12: 9360 | F12: 16020 | G12: 390 | H12: I-CAM | I12: 0 | J12: 0 | K12: =IFERROR(J12/I12*100,0) -> 0 | L12: 26.5 | M12: =J12*E_Data!$B$4/1000 -> 0 | N12: =IF(L12=0,"N/A",IF(K12=0,"No data",IF(K12<=L12*1.05,"✓ Good",IF(K12<=L12*1.15,"⚠ Alert","🔴 High")))) -> No data
A13: LB45BXGP | B13: SGTBLOEM | C13: HINO 1627 16T Curtain | D13: 25380 | E13: 9360 | F13: 16020 | G13: 390 | H13: I-CAM | I13: 0 | J13: 0 | K13: =IFERROR(J13/I13*100,0) -> 0 | L13: 26.5 | M13: =J13*E_Data!$B$4/1000 -> 0 | N13: =IF(L13=0,"N/A",IF(K13=0,"No data",IF(K13<=L13*1.05,"✓ Good",IF(K13<=L13*1.15,"⚠ Alert","🔴 High")))) -> No data
A14: LC36DCGP | B14: SGTBLOEM | C14: HINO 500 1627 16T Fridge | D14: 25380 | E14: 9340 | F14: 16040 | G14: 390 | H14: I-CAM | I14: 0 | J14: 0 | K14: =IFERROR(J14/I14*100,0) -> 0 | L14: 26.5 | M14: =J14*E_Data!$B$4/1000 -> 0 | N14: =IF(L14=0,"N/A",IF(K14=0,"No data",IF(K14<=L14*1.05,"✓ Good",IF(K14<=L14*1.15,"⚠ Alert","🔴 High")))) -> No data
A15: MK66VTGP | B15: SGTSPFMCG | C15: HINO 700 32T | D15: 42000 | E15: 9060 | F15: 32940 | G15: 1000 | H15: I-CAM | I15: 0 | J15: 0 | K15: =IFERROR(J15/I15*100,0) -> 0 | L15: 55 | M15: =J15*E_Data!$B$4/1000 -> 0 | N15: =IF(L15=0,"N/A",IF(K15=0,"No data",IF(K15<=L15*1.05,"✓ Good",IF(K15<=L15*1.15,"⚠ Alert","🔴 High")))) -> No data
... A19: LC09YVGP | B19: SGTPE | C19: HINO 1627 16T Curtain | D19: 25380 | E19: 9320 | F19: 16060 | G19: 390 | H19: I-CAM | I19: 0 | J19: 0 | K19: =IFERROR(J19/I19*100,0) -> 0 | L19: 26.5 | M19: =J19*E_Data!$B$4/1000 -> 0 | N19: =IF(L19=0,"N/A",IF(K19=0,"No data",IF(K19<=L19*1.05,"✓ Good",IF(K19<=L19*1.15,"⚠ Alert","🔴 High")))) -> No data
A21: FLEET SUMMARY (from Fleet Summary Totals Per Type sheet)
A22: Depot | B22: Total Vehicles | C22: 32T Scania | D22: 16T | E22: 8T | F22: 4T | G22: Trailers | H22: EV Vehicles
A23: SGTBLOEM | B23: 16 | C23: 2 | D23: 7 | E23: 2 | F23: 0 | G23: 4 | H23: 0
A24: SGTCPT | B24: 14 | C24: 2 | D24: 2 | E24: 3 | F24: 3 | G24: 4 | H24: 0
A25: SGTDBN | B25: 19 | C25: 3 | D25: 8 | E25: 3 | F25: 0 | G25: 4 | H25: 0
A26: SGTPE | B26: 6 | C26: 0 | D26: 1 | E26: 3 | F26: 2 | G26: 0 | H26: 0
A27: SGTSPFMCG | B27: 79 | C27: 12 | D27: 7 | E27: 11 | F27: 8 | G27: 34 | H27: 0
A28: TOTAL | B28: 134 | C28: 19 | D28: 25 | E28: 22 | F28: 13 | G28: 46 | H28: 0
A30: EV FLEET TRANSITION PLAN | MAXUS eDeliver 3 (3.5T, range 330km) & eDeliver 5 (1T, range 320km) | Target: 20% EV mix by 2030 | EF_SOLAR offset applies to EV charging
A31: EV Model | B31: Range (km) | C31: Payload (kg) | D31: Charge kWh | E31: tCO₂e/km (grid) | F31: vs Diesel saving | G31: Recommended depot
A32: MAXUS eDeliver 3 | B32: 330 | C32: 900 | D32: 35 | E32: =E_Data!$B$7*35/330/1000 -> 8.6969697e-05 | F32: =IFERROR(D32*0.0001,0) -> 0.0035 | G32: CPT/PE short runs
A33: MAXUS eDeliver 5 | B33: 320 | C33: 1075 | D33: 42 | E33: =E_Data!$B$7*42/320/1000 -> 0.000107625 | F33: =IFERROR(D33*0.0001,0) -> 0.0042 | G33: BLOEM/JHB urban

Sheet ISO_14083
A1: 🚚 ISO 14083 / GLEC — TRANSPORT EMISSIONS | Per-trip · Intensity · Customer Allocation
A2: ISO 14083:2023 quantification methodology for transport chain GHG emissions. Calculates emissions at journey/leg level, enables intensity metrics (gCO₂e/t·km), and supports per-customer allocation for client-ready reporting. See Glossary for ISO 14083, GLEC, t·km, TKM, allocation methods.
A4: BLOCK 1 — TRIP REGISTER | Each row = one trip/journey | Pre-seeded with Apr-26 data from Driver_Debrief
A5: Trip ID | B5: Date | C5: Depot | D5: Vehicle Reg | E5: Route ID | F5: Mode | G5: Vehicle Class | H5: Fuel Type | I5: Distance (km) | J5: Load (tonnes) | K5: Tonne-km (t·km) | L5: Customer | M5: Allocation Basis | N5: Loaded? | O5: Fuel Used (L)
A6: T-26040001 | B6: 2026-04-01 | C6: SGTPE | D6: KZ00LRGP | E6: 010426EJ002 | F6: Road | G6: Light | H6: Diesel | I6: 2 | J6: 0.5 | K6: =IFERROR(I6*J6,0) -> 1 | L6: Engen Express | M6: Weight | N6: Yes
A7: T-26040002 | B7: 2026-04-01 | C7: SGTPE | D7: LC09YVGP | E7: 010426EJ005 | F7: Road | G7: Heavy | H7: Diesel | I7: 1 | J7: 8 | K7: =IFERROR(I7*J7,0) -> 8 | L7: Engen Express | M7: Weight | N7: Yes
A8: T-26040003 | B8: 2026-04-01 | C8: SGTPE | D8: KZ00LRGP | E8: 010426EL001 | F8: Road | G8: Light | H8: Diesel | I8: 37 | J8: 1.2 | K8: =IFERROR(I8*J8,0) -> 44.4 | L8: Engen Logistics | M8: Weight | N8: Yes
A9: T-26040004 | B9: 2026-04-01 | C9: SGTPE | D9: LC22HRGP | E9: 010426EL003 | F9: Road | G9: Medium | H9: Diesel | I9: 55 | J9: 3.8 | K9: =IFERROR(I9*J9,0) -> 209 | L9: Engen Logistics | M9: Weight | N9: Yes
A10: T-26040005 | B10: 2026-04-01 | C10: SGTBLOEM | D10: LB45BMGP | E10: 010426FC001 | F10: Road | G10: Heavy | H10: Diesel | I10: 449 | J10: 16 | K10: =IFERROR(I10*J10,0) -> 7184 | L10: Famous Brands | M10: Weight | N10: Yes
A11: T-26040006 | B11: 2026-04-01 | C11: SGTBLOEM | D11: LB45BMGP | E11: 010426FL001 | F11: Road | G11: Heavy | H11: Diesel | I11: 28 | J11: 12.5 | K11: =IFERROR(I11*J11,0) -> 350 | L11: Famous Brands | M11: Weight | N11: Yes
A12: T-26040007 | B12: 2026-04-01 | C12: SGTSPFMCG | D12: KZ97BKGP | E12: 010426GC001 | F12: Road | G12: Heavy | H12: Diesel | I12: 972 | J12: 8 | K12: =IFERROR(I12*J12,0) -> 7776 | L12: Shared (3 customers) | M12: Weight | N12: Yes
K13: =IFERROR(I13*J13,0) -> 0
K14: =IFERROR(I14*J14,0) -> 0
K15: =IFERROR(I15*J15,0) -> 0
K16: =IFERROR(I16*J16,0) -> 0
K17: =IFERROR(I17*J17,0) -> 0
K18: =IFERROR(I18*J18,0) -> 0
K19: =IFERROR(I19*J19,0) -> 0
K20: =IFERROR(I20*J20,0) -> 0
K21: =IFERROR(I21*J21,0) -> 0
K22: =IFERROR(I22*J22,0) -> 0
K23: =IFERROR(I23*J23,0) -> 0
K24: =IFERROR(I24*J24,0) -> 0
K25: =IFERROR(I25*J25,0) -> 0
A26: TOTAL | I26: =SUM(I6:I25) -> 1544 | J26: =SUM(J6:J25) -> 50 | K26: =SUM(K6:K25) -> 15572.4 | O26: =SUM(O6:O25) -> 0
A28: BLOCK 2 — PER-TRIP EMISSIONS | Fuel-based (preferred) or distance-based fallback per ISO 14083 §7
A29: Trip ID | B29: Method | C29: Fuel kgCO₂e | D29: Dist kgCO₂e | E29: Trip tCO₂e | F29: gCO₂e/km | G29: gCO₂e/t·km | H29: Customer | I29: Customer tCO₂e | J29: Empty trip? | K29: Intensity vs avg
A30: =IF(A6="","",A6) -> T-26040001 | B30: =IF(A6="","",IF(O6>0,"Fuel-based","Distance-based")) -> Distance-based | C30: =IFERROR(IF(O6>0,IF(H6="Diesel",O6*Assumptions!$B$30,IF(H6="Petrol",O6*Assumptions!$B$31,IF(H6="LPG",O6*Assumptions!$B$32,IF(H6="Electric",I6*0.35*Assumptions!$B$33,O6*Assumptions!$B$30)))),""),"") | D30: =IFERROR(I6*IF(G6="Light",18,IF(G6="Medium",22,IF(G6="Heavy",26.5,IF(G6="Articulated",35,22))))/100*Assumptions!$B$30,0) -> 0.9648 | E30: =IFERROR(IF(A6="","",IF(O6>0,C30,D30)/1000),0) -> 0.0009648 | F30: =IFERROR(E30*1000000/I6,0) -> 482.4 | G30: =IFERROR(E30*1000000/K6,0) -> 964.8 | H30: =IF(L6="","",L6) -> Engen Express | I30: =IFERROR(IF(L6="","",IF(ISNUMBER(SEARCH("Shared",L6)),E30/3,E30)),"") -> 0.0009648 | J30: =IF(A6="","",IF(N6="No","⚠ Backhaul","")) | K30: =IF(A6="","",IF(G30<=80,"✓ Best",IF(G30<=150,"○ Good",IF(G30<=300,"⚠ Avg","✗ High")))) -> ✗ High
A31: =IF(A7="","",A7) -> T-26040002 | B31: =IF(A7="","",IF(O7>0,"Fuel-based","Distance-based")) -> Distance-based | C31: =IFERROR(IF(O7>0,IF(H7="Diesel",O7*Assumptions!$B$30,IF(H7="Petrol",O7*Assumptions!$B$31,IF(H7="LPG",O7*Assumptions!$B$32,IF(H7="Electric",I7*0.35*Assumptions!$B$33,O7*Assumptions!$B$30)))),""),"") | D31: =IFERROR(I7*IF(G7="Light",18,IF(G7="Medium",22,IF(G7="Heavy",26.5,IF(G7="Articulated",35,22))))/100*Assumptions!$B$30,0) -> 0.7102 | E31: =IFERROR(IF(A7="","",IF(O7>0,C31,D31)/1000),0) -> 0.0007102 | F31: =IFERROR(E31*1000000/I7,0) -> 710.2 | G31: =IFERROR(E31*1000000/K7,0) -> 88.775 | H31: =IF(L7="","",L7) -> Engen Express | I31: =IFERROR(IF(L7="","",IF(ISNUMBER(SEARCH("Shared",L7)),E31/3,E31)),"") -> 0.0007102 | J31: =IF(A7="","",IF(N7="No","⚠ Backhaul","")) | K31: =IF(A7="","",IF(G31<=80,"✓ Best",IF(G31<=150,"○ Good",IF(G31<=300,"⚠ Avg","✗ High")))) -> ○ Good
A32: =IF(A8="","",A8) -> T-26040003 | B32: =IF(A8="","",IF(O8>0,"Fuel-based","Distance-based")) -> Distance-based | C32: =IFERROR(IF(O8>0,IF(H8="Diesel",O8*Assumptions!$B$30,IF(H8="Petrol",O8*Assumptions!$B$31,IF(H8="LPG",O8*Assumptions!$B$32,IF(H8="Electric",I8*0.35*Assumptions!$B$33,O8*Assumptions!$B$30)))),""),"") | D32: =IFERROR(I8*IF(G8="Light",18,IF(G8="Medium",22,IF(G8="Heavy",26.5,IF(G8="Articulated",35,22))))/100*Assumptions!$B$30,0) -> 17.8488 | E32: =IFERROR(IF(A8="","",IF(O8>0,C32,D32)/1000),0) -> 0.0178488 | F32: =IFERROR(E32*1000000/I8,0) -> 482.4 | G32: =IFERROR(E32*1000000/K8,0) -> 402 | H32: =IF(L8="","",L8) -> Engen Logistics | I32: =IFERROR(IF(L8="","",IF(ISNUMBER(SEARCH("Shared",L8)),E32/3,E32)),"") -> 0.0178488 | J32: =IF(A8="","",IF(N8="No","⚠ Backhaul","")) | K32: =IF(A8="","",IF(G32<=80,"✓ Best",IF(G32<=150,"○ Good",IF(G32<=300,"⚠ Avg","✗ High")))) -> ✗ High
A33: =IF(A9="","",A9) -> T-26040004 | B33: =IF(A9="","",IF(O9>0,"Fuel-based","Distance-based")) -> Distance-based | C33: =IFERROR(IF(O9>0,IF(H9="Diesel",O9*Assumptions!$B$30,IF(H9="Petrol",O9*Assumptions!$B$31,IF(H9="LPG",O9*Assumptions!$B$32,IF(H9="Electric",I9*0.35*Assumptions!$B$33,O9*Assumptions!$B$30)))),""),"") | D33: =IFERROR(I9*IF(G9="Light",18,IF(G9="Medium",22,IF(G9="Heavy",26.5,IF(G9="Articulated",35,22))))/100*Assumptions!$B$30,0) -> 32.428 | E33: =IFERROR(IF(A9="","",IF(O9>0,C33,D33)/1000),0) -> 0.032428 | F33: =IFERROR(E33*1000000/I9,0) -> 589.6 | G33: =IFERROR(E33*1000000/K9,0) -> 155.15789 | H33: =IF(L9="","",L9) -> Engen Logistics | I33: =IFERROR(IF(L9="","",IF(ISNUMBER(SEARCH("Shared",L9)),E33/3,E33)),"") -> 0.032428 | J33: =IF(A9="","",IF(N9="No","⚠ Backhaul","")) | K33: =IF(A9="","",IF(G33<=80,"✓ Best",IF(G33<=150,"○ Good",IF(G33<=300,"⚠ Avg","✗ High")))) -> ⚠ Avg
A34: =IF(A10="","",A10) -> T-26040005 | B34: =IF(A10="","",IF(O10>0,"Fuel-based","Distance-based")) -> Distance-based | C34: =IFERROR(IF(O10>0,IF(H10="Diesel",O10*Assumptions!$B$30,IF(H10="Petrol",O10*Assumptions!$B$31,IF(H10="LPG",O10*Assumptions!$B$32,IF(H10="Electric",I10*0.35*Assumptions!$B$33,O10*Assumptions!$B$30)))),""),"") | D34: =IFERROR(I10*IF(G10="Light",18,IF(G10="Medium",22,IF(G10="Heavy",26.5,IF(G10="Articulated",35,22))))/100*Assumptions!$B$30,0) -> 318.8798 | E34: =IFERROR(IF(A10="","",IF(O10>0,C34,D34)/1000),0) -> 0.3188798 | F34: =IFERROR(E34*1000000/I10,0) -> 710.2 | G34: =IFERROR(E34*1000000/K10,0) -> 44.3875 | H34: =IF(L10="","",L10) -> Famous Brands | I34: =IFERROR(IF(L10="","",IF(ISNUMBER(SEARCH("Shared",L10)),E34/3,E34)),"") -> 0.3188798 | J34: =IF(A10="","",IF(N10="No","⚠ Backhaul","")) | K34: =IF(A10="","",IF(G34<=80,"✓ Best",IF(G34<=150,"○ Good",IF(G34<=300,"⚠ Avg","✗ High")))) -> ✓ Best
A35: =IF(A11="","",A11) -> T-26040006 | B35: =IF(A11="","",IF(O11>0,"Fuel-based","Distance-based")) -> Distance-based | C35: =IFERROR(IF(O11>0,IF(H11="Diesel",O11*Assumptions!$B$30,IF(H11="Petrol",O11*Assumptions!$B$31,IF(H11="LPG",O11*Assumptions!$B$32,IF(H11="Electric",I11*0.35*Assumptions!$B$33,O11*Assumptions!$B$30)))),""),"") | D35: =IFERROR(I11*IF(G11="Light",18,IF(G11="Medium",22,IF(G11="Heavy",26.5,IF(G11="Articulated",35,22))))/100*Assumptions!$B$30,0) -> 19.8856 | E35: =IFERROR(IF(A11="","",IF(O11>0,C35,D35)/1000),0) -> 0.0198856 | F35: =IFERROR(E35*1000000/I11,0) -> 710.2 | G35: =IFERROR(E35*1000000/K11,0) -> 56.816 | H35: =IF(L11="","",L11) -> Famous Brands | I35: =IFERROR(IF(L11="","",IF(ISNUMBER(SEARCH("Shared",L11)),E35/3,E35)),"") -> 0.0198856 | J35: =IF(A11="","",IF(N11="No","⚠ Backhaul","")) | K35: =IF(A11="","",IF(G35<=80,"✓ Best",IF(G35<=150,"○ Good",IF(G35<=300,"⚠ Avg","✗ High")))) -> ✓ Best
A36: =IF(A12="","",A12) -> T-26040007 | B36: =IF(A12="","",IF(O12>0,"Fuel-based","Distance-based")) -> Distance-based | C36: =IFERROR(IF(O12>0,IF(H12="Diesel",O12*Assumptions!$B$30,IF(H12="Petrol",O12*Assumptions!$B$31,IF(H12="LPG",O12*Assumptions!$B$32,IF(H12="Electric",I12*0.35*Assumptions!$B$33,O12*Assumptions!$B$30)))),""),"") | D36: =IFERROR(I12*IF(G12="Light",18,IF(G12="Medium",22,IF(G12="Heavy",26.5,IF(G12="Articulated",35,22))))/100*Assumptions!$B$30,0) -> 690.3144 | E36: =IFERROR(IF(A12="","",IF(O12>0,C36,D36)/1000),0) -> 0.6903144 | F36: =IFERROR(E36*1000000/I12,0) -> 710.2 | G36: =IFERROR(E36*1000000/K12,0) -> 88.775 | H36: =IF(L12="","",L12) -> Shared (3 customers) | I36: =IFERROR(IF(L12="","",IF(ISNUMBER(SEARCH("Shared",L12)),E36/3,E36)),"") -> 0.2301048 | J36: =IF(A12="","",IF(N12="No","⚠ Backhaul","")) | K36: =IF(A12="","",IF(G36<=80,"✓ Best",IF(G36<=150,"○ Good",IF(G36<=300,"⚠ Avg","✗ High")))) -> ○ Good
A37: =IF(A13="","",A13) | B37: =IF(A13="","",IF(O13>0,"Fuel-based","Distance-based")) | C37: =IFERROR(IF(O13>0,IF(H13="Diesel",O13*Assumptions!$B$30,IF(H13="Petrol",O13*Assumptions!$B$31,IF(H13="LPG",O13*Assumptions!$B$32,IF(H13="Electric",I13*0.35*Assumptions!$B$33,O13*Assumptions!$B$30)))),""),"") | D37: =IFERROR(I13*IF(G13="Light",18,IF(G13="Medium",22,IF(G13="Heavy",26.5,IF(G13="Articulated",35,22))))/100*Assumptions!$B$30,0) -> 0 | E37: =IFERROR(IF(A13="","",IF(O13>0,C37,D37)/1000),0) | F37: =IFERROR(E37*1000000/I13,0) -> 0 | G37: =IFERROR(E37*1000000/K13,0) -> 0 | H37: =IF(L13="","",L13) | I37: =IFERROR(IF(L13="","",IF(ISNUMBER(SEARCH("Shared",L13)),E37/3,E37)),"") | J37: =IF(A13="","",IF(N13="No","⚠ Backhaul","")) | K37: =IF(A13="","",IF(G37<=80,"✓ Best",IF(G37<=150,"○ Good",IF(G37<=300,"⚠ Avg","✗ High"))))
A38: =IF(A14="","",A14) | B38: =IF(A14="","",IF(O14>0,"Fuel-based","Distance-based")) | C38: =IFERROR(IF(O14>0,IF(H14="Diesel",O14*Assumptions!$B$30,IF(H14="Petrol",O14*Assumptions!$B$31,IF(H14="LPG",O14*Assumptions!$B$32,IF(H14="Electric",I14*0.35*Assumptions!$B$33,O14*Assumptions!$B$30)))),""),"") | D38: =IFERROR(I14*IF(G14="Light",18,IF(G14="Medium",22,IF(G14="Heavy",26.5,IF(G14="Articulated",35,22))))/100*Assumptions!$B$30,0) -> 0 | E38: =IFERROR(IF(A14="","",IF(O14>0,C38,D38)/1000),0) | F38: =IFERROR(E38*1000000/I14,0) -> 0 | G38: =IFERROR(E38*1000000/K14,0) -> 0 | H38: =IF(L14="","",L14) | I38: =IFERROR(IF(L14="","",IF(ISNUMBER(SEARCH("Shared",L14)),E38/3,E38)),"") | J38: =IF(A14="","",IF(N14="No","⚠ Backhaul","")) | K38: =IF(A14="","",IF(G38<=80,"✓ Best",IF(G38<=150,"○ Good",IF(G38<=300,"⚠ Avg","✗ High"))))
A39: =IF(A15="","",A15) | B39: =IF(A15="","",IF(O15>0,"Fuel-based","Distance-based")) | C39: =IFERROR(IF(O15>0,IF(H15="Diesel",O15*Assumptions!$B$30,IF(H15="Petrol",O15*Assumptions!$B$31,IF(H15="LPG",O15*Assumptions!$B$32,IF(H15="Electric",I15*0.35*Assumptions!$B$33,O15*Assumptions!$B$30)))),""),"") | D39: =IFERROR(I15*IF(G15="Light",18,IF(G15="Medium",22,IF(G15="Heavy",26.5,IF(G15="Articulated",35,22))))/100*Assumptions!$B$30,0) -> 0 | E39: =IFERROR(IF(A15="","",IF(O15>0,C39,D39)/1000),0) | F39: =IFERROR(E39*1000000/I15,0) -> 0 | G39: =IFERROR(E39*1000000/K15,0) -> 0 | H39: =IF(L15="","",L15) | I39: =IFERROR(IF(L15="","",IF(ISNUMBER(SEARCH("Shared",L15)),E39/3,E39)),"") | J39: =IF(A15="","",IF(N15="No","⚠ Backhaul","")) | K39: =IF(A15="","",IF(G39<=80,"✓ Best",IF(G39<=150,"○ Good",IF(G39<=300,"⚠ Avg","✗ High"))))
A40: =IF(A16="","",A16) | B40: =IF(A16="","",IF(O16>0,"Fuel-based","Distance-based")) | C40: =IFERROR(IF(O16>0,IF(H16="Diesel",O16*Assumptions!$B$30,IF(H16="Petrol",O16*Assumptions!$B$31,IF(H16="LPG",O16*Assumptions!$B$32,IF(H16="Electric",I16*0.35*Assumptions!$B$33,O16*Assumptions!$B$30)))),""),"") | D40: =IFERROR(I16*IF(G16="Light",18,IF(G16="Medium",22,IF(G16="Heavy",26.5,IF(G16="Articulated",35,22))))/100*Assumptions!$B$30,0) -> 0 | E40: =IFERROR(IF(A16="","",IF(O16>0,C40,D40)/1000),0) | F40: =IFERROR(E40*1000000/I16,0) -> 0 | G40: =IFERROR(E40*1000000/K16,0) -> 0 | H40: =IF(L16="","",L16) | I40: =IFERROR(IF(L16="","",IF(ISNUMBER(SEARCH("Shared",L16)),E40/3,E40)),"") | J40: =IF(A16="","",IF(N16="No","⚠ Backhaul","")) | K40: =IF(A16="","",IF(G40<=80,"✓ Best",IF(G40<=150,"○ Good",IF(G40<=300,"⚠ Avg","✗ High"))))
A41: =IF(A17="","",A17) | B41: =IF(A17="","",IF(O17>0,"Fuel-based","Distance-based")) | C41: =IFERROR(IF(O17>0,IF(H17="Diesel",O17*Assumptions!$B$30,IF(H17="Petrol",O17*Assumptions!$B$31,IF(H17="LPG",O17*Assumptions!$B$32,IF(H17="Electric",I17*0.35*Assumptions!$B$33,O17*Assumptions!$B$30)))),""),"") | D41: =IFERROR(I17*IF(G17="Light",18,IF(G17="Medium",22,IF(G17="Heavy",26.5,IF(G17="Articulated",35,22))))/100*Assumptions!$B$30,0) -> 0 | E41: =IFERROR(IF(A17="","",IF(O17>0,C41,D41)/1000),0) | F41: =IFERROR(E41*1000000/I17,0) -> 0 | G41: =IFERROR(E41*1000000/K17,0) -> 0 | H41: =IF(L17="","",L17) | I41: =IFERROR(IF(L17="","",IF(ISNUMBER(SEARCH("Shared",L17)),E41/3,E41)),"") | J41: =IF(A17="","",IF(N17="No","⚠ Backhaul","")) | K41: =IF(A17="","",IF(G41<=80,"✓ Best",IF(G41<=150,"○ Good",IF(G41<=300,"⚠ Avg","✗ High"))))
... A49: =IF(A25="","",A25) | B49: =IF(A25="","",IF(O25>0,"Fuel-based","Distance-based")) | C49: =IFERROR(IF(O25>0,IF(H25="Diesel",O25*Assumptions!$B$30,IF(H25="Petrol",O25*Assumptions!$B$31,IF(H25="LPG",O25*Assumptions!$B$32,IF(H25="Electric",I25*0.35*Assumptions!$B$33,O25*Assumptions!$B$30)))),""),"") | D49: =IFERROR(I25*IF(G25="Light",18,IF(G25="Medium",22,IF(G25="Heavy",26.5,IF(G25="Articulated",35,22))))/100*Assumptions!$B$30,0) -> 0 | E49: =IFERROR(IF(A25="","",IF(O25>0,C49,D49)/1000),0) | F49: =IFERROR(E49*1000000/I25,0) -> 0 | G49: =IFERROR(E49*1000000/K25,0) -> 0 | H49: =IF(L25="","",L25) | I49: =IFERROR(IF(L25="","",IF(ISNUMBER(SEARCH("Shared",L25)),E49/3,E49)),"") | J49: =IF(A25="","",IF(N25="No","⚠ Backhaul","")) | K49: =IF(A25="","",IF(G49<=80,"✓ Best",IF(G49<=150,"○ Good",IF(G49<=300,"⚠ Avg","✗ High"))))
...

Sheet Waste_Register
A1: WASTE REGISTER — Oricol Environmental | Oracle | Valour Brands | Cority [GRI 306 | ISO 14001 | Net-Zero]
A3: WASTE STREAMS — Monthly data entry [Source: Waste contractors + Cority cardboard data]
A4: Month | B4: Depot | C4: Waste Type | D4: Total kg | E4: Recycled kg | F4: Landfill kg | G4: Diverted % | H4: Landfill tCO₂e | I4: Contractor | J4: Invoice Ref
A5: Mar-26 | B5: CPT | C5: Commercial/Industrial (landfill) | D5: 2000 | E5: 0 | F5: 2000 | G5: =IFERROR(E5/D5,0) -> 0 | H5: =F5*0.58/1000 -> 1.16 | I5: Oricol Environmental | J5: Mar-26 actual
A6: Mar-26 | B6: CPT | C6: Commercial/Industrial (recycled) | D6: 6580 | E6: 6580 | F6: 0 | G6: =IFERROR(E6/D6,0) -> 1 | H6: =F6*0.58/1000 -> 0 | I6: Oricol Environmental | J6: Mar-26 actual
A7: Mar-26 | B7: CPT | C7: Paper/Cardboard K4 | D7: 1100 | E7: 1100 | F7: 0 | G7: =IFERROR(E7/D7,0) -> 1 | H7: =F7*0.58/1000 -> 0 | I7: Oricol Environmental | J7: Mar-26 actual
A8: Mar-26 | B8: CPT | C8: LDPE Shrinkwrap | D8: 880 | E8: 880 | F8: 0 | G8: =IFERROR(E8/D8,0) -> 1 | H8: =F8*0.58/1000 -> 0 | I8: Oricol Environmental | J8: Mar-26 actual
A9: Mar-26 | B9: ALL | C9: TOTAL (Oricol Big Numbers) | D9: 22470 | E9: 20470 | F9: 2000 | G9: 91.1% | H9: =F9*0.58/1000 -> 1.16 | I9: Oricol Environmental | J9: Oricol Big Numbers
A11: CORITY CARDBOARD RECYCLING % — Monthly (from Mariette Dashboard waste sheet)
A12: Month | B12: Jul-25 | C12: Aug-25 | D12: Sep-25 | E12: Oct-25 | F12: Nov-25 | G12: Dec-25 | H12: Jan-26 | I12: Feb-26 | J12: Mar-26
A13: % Recycled (all depots) | B13: 0.1065 | C13: 0.1624 | D13: 0.1106 | E13: 0.0889 | F13: 0.2642 | G13: 0.1068 | H13: 0.046 | I13: 0.1373 | J13: 0.0956
A15: WASTE SCORECARD — vs ISO 14001 + Net-Zero targets
A16: Oricol CPT diversion rate (Mar-26) | B16: =91.1% -> 0.911 | C16: ≥90% | D16: ✓ Met | E16: 5
A17: Average monthly % recycled (Cority) | B17: =AVERAGE(B13:J13) -> 0.12425556 | C17: ≥25% | E17: 4
A18: Total landfill tCO₂e YTD | B18: =SUMIF(F4:F40,">0",F4:F40)*0.58/1000 -> 2.3201532 | C18: Minimise | E18: 3
A19: Waste contractor sustainability rating | B19: IMS-T-149 Oricol score | C19: ≥80% | E19: 3
A20: ISO 14001 waste aspect managed | C20: Yes | E20: 3

Sheet Driver_Debrief
A1: DRIVER DEBRIEF — Route Completion | Customer Hit % | Planned vs Actual km | Net-Zero km Efficiency [Source: DriverDebriefSummary.xlsx]
A3: Date | B3: Depot | C3: Driver Name | D3: Vehicle Reg | E3: Route | F3: Cust Hit% | G3: Plan Stops | H3: Act Stops | I3: Variance | J3: Plan km | K3: Act km | L3: km Excess | M3: Net-Zero Note / Action
A4: 2026-04-01 | B4: SGTPE | C4: Hubrey Malgas | D4: KZ00LRGP | E4: 010426EJ002 | F4: 1 | G4: 1 | H4: 1 | I4: 0 | J4: 2 | K4: 2 | L4: =K4-J4 -> 0 | M4: ✓ On route
A5: 2026-04-01 | B5: SGTPE | C5: NO DATA | D5: LC09YVGP | E5: 010426EJ005 | F5: 1 | G5: 1 | H5: 1 | I5: 0 | J5: 1 | K5: 1 | L5: =K5-J5 -> 0 | M5: ✓ On route
A6: 2026-04-01 | B6: SGTPE | C6: Hubrey Malgas | D6: KZ00LRGP | E6: 010426EL001 | F6: 1 | G6: 3 | H6: 3 | I6: 0 | J6: 37 | K6: 37 | L6: =K6-J6 -> 0 | M6: ✓ On route
A7: 2026-04-01 | B7: SGTPE | C7: James Jantjies | D7: LC22HRGP | E7: 010426EL003 | F7: 0.85 | G7: 7 | H7: 6 | I7: 1 | J7: 55 | K7: 55 | L7: =K7-J7 -> 0 | M7: ✓ On route
A8: 2026-04-01 | B8: SGTBLOEM | C8: TG Kwababa | D8: LB45BMGP | E8: 010426FC001 | F8: 1 | G8: 4 | H8: 4 | I8: 0 | J8: 449 | K8: 449 | L8: =K8-J8 -> 0 | M8: ✓ On route
A9: 2026-04-01 | B9: SGTBLOEM | C9: G Kwababa | D9: LB45BMGP | E9: 010426FL001 | F9: 1 | G9: 2 | H9: 2 | I9: 0 | J9: 28 | K9: 28 | L9: =K9-J9 -> 0 | M9: ✓ On route
A10: 2026-04-01 | B10: SGTSPFMCG | C10: Osbar Naka | D10: KZ97BKGP | E10: 010426GC001 | F10: 0.66 | G10: 15 | H10: 10 | I10: 5 | J10: 847 | K10: 972 | L10: =K10-J10 -> 125 | M10: ⚠ 66% hit rate — 5 stops missed, 125km excess — fatigue/routing review required
A11: → ADD NEW DEBRIEF ROWS BELOW (paste from DriverDebriefSummary.xlsx export)
L12: =IFERROR(K12-J12,0) -> 0
L13: =IFERROR(K13-J13,0) -> 0
L14: =IFERROR(K14-J14,0) -> 0
L15: =IFERROR(K15-J15,0) -> 0
L16: =IFERROR(K16-J16,0) -> 0
L17: =IFERROR(K17-J17,0) -> 0
L18: =IFERROR(K18-J18,0) -> 0
L19: =IFERROR(K19-J19,0) -> 0
L20: =IFERROR(K20-J20,0) -> 0
L21: =IFERROR(K21-J21,0) -> 0
L22: =IFERROR(K22-J22,0) -> 0
L23: =IFERROR(K23-J23,0) -> 0
... L41: =IFERROR(K41-J41,0) -> 0
A44: DEBRIEF KPI SUMMARY — feeds S_Scorecard and Net-Zero km efficiency
A45: KPI | B45: Value | C45: Benchmark
A46: Average Customer Hit % | B46: =IFERROR(AVERAGEIF(F4:F40,">0",F4:F40),0) -> 0.93 | C46: ≥95% = full score
A47: Total Excess km (waste driving) | B47: =IFERROR(SUM(L4:L40),0) -> 125 | C47: Target: 0 excess km
A48: Excess km as % of total planned | B48: =IFERROR(SUM(L4:L40)/SUM(J4:J40),0) -> 0.088090204 | C48: Target: <2%
A49: Estimated Scope 1 from excess km | B49: =IFERROR(SUM(L4:L40)*0.003,0) -> 0.375 | C49: Fleet avg CO₂/km estimate
A50: Routes <80% customer hit rate | B50: =IFERROR(COUNTIF(F4:F40,"<0.8"),0) -> 1 | C50: Target: 0
A51: Driver fatigue flags this period | B51: =0 -> 0 | C51: Target: 0

Sheet S_Data
A1: S_DATA — SOCIAL RAW DATA | H&S · EE Headcount · Training · Community [Sources: Accidently / HR / SETA / Cority]
A3: EMPLOYMENT EQUITY — HEADCOUNT BY OCCUPATIONAL LEVEL & RACE [EEA2 format | Source: HR payroll system]
A4: Occupational Level | B4: Af M | C4: Col M | D4: Ind M | E4: Wht M | F4: Af F | G4: Col F | H4: Ind F | I4: Wht F | J4: For M | K4: For F | L4: TOTAL
A5: Top Management (EEA2 L1) | B5: 0 | C5: 0 | D5: 0 | E5: 0 | F5: 0 | G5: 0 | H5: 0 | I5: 0 | J5: 0 | K5: 0 | L5: =SUM(B5:K5) -> 0
A6: Senior Management (EEA2 L2) | B6: 0 | C6: 0 | D6: 0 | E6: 0 | F6: 0 | G6: 0 | H6: 0 | I6: 0 | J6: 0 | K6: 0 | L6: =SUM(B6:K6) -> 0
A7: Professionally Qualified (EEA2 L3) | B7: 0 | C7: 0 | D7: 0 | E7: 0 | F7: 0 | G7: 0 | H7: 0 | I7: 0 | J7: 0 | K7: 0 | L7: =SUM(B7:K7) -> 0
A8: Skilled Technical (EEA2 L4) | B8: 0 | C8: 0 | D8: 0 | E8: 0 | F8: 0 | G8: 0 | H8: 0 | I8: 0 | J8: 0 | K8: 0 | L8: =SUM(B8:K8) -> 0
A9: Semi-Skilled (EEA2 L5) | B9: 0 | C9: 0 | D9: 0 | E9: 0 | F9: 0 | G9: 0 | H9: 0 | I9: 0 | J9: 0 | K9: 0 | L9: =SUM(B9:K9) -> 0
A10: Unskilled (EEA2 L6) | B10: 0 | C10: 0 | D10: 0 | E10: 0 | F10: 0 | G10: 0 | H10: 0 | I10: 0 | J10: 0 | K10: 0 | L10: =SUM(B10:K10) -> 0
A11: Non-Permanent | B11: 0 | C11: 0 | D11: 0 | E11: 0 | F11: 0 | G11: 0 | H11: 0 | I11: 0 | J11: 0 | K11: 0 | L11: =SUM(B11:K11) -> 0
A12: TOTAL ALL LEVELS | B12: =SUM(B5,B6,B7,B8,B9,B10,B11) -> 0 | C12: =SUM(C5,C6,C7,C8,C9,C10,C11) -> 0 | D12: =SUM(D5,D6,D7,D8,D9,D10,D11) -> 0 | E12: =SUM(E5,E6,E7,E8,E9,E10,E11) -> 0 | F12: =SUM(F5,F6,F7,F8,F9,F10,F11) -> 0 | G12: =SUM(G5,G6,G7,G8,G9,G10,G11) -> 0 | H12: =SUM(H5,H6,H7,H8,H9,H10,H11) -> 0 | I12: =SUM(I5,I6,I7,I8,I9,I10,I11) -> 0 | ... L12: =SUM(L5,L6,L7,L8,L9,L10,L11) -> 0
A14: EE TARGETS & GAP ANALYSIS [EEA Section 20 targets]
A15: Level | B15: Total | C15: % Black | D15: Target % Black | E15: % Black Female | F15: Target % BlkF | G15: % PWD | H15: Target % PWD | I15: Gap Black | J15: Score /10
A16: Top Management (EEA2 L1) | B16: =S_Data!L5 -> 0 | C16: =IFERROR((S_Data!B5+S_Data!C5+S_Data!D5+S_Data!F5+S_Data!G5+S_Data!H5)/S_Data!L5,0) -> 0 | D16: 0.55 | E16: =IFERROR((S_Data!F5+S_Data!G5+S_Data!H5)/S_Data!L5,0) -> 0 | F16: 0.3 | G16: =0 -> 0 | H16: 0.02 | I16: =C16-D16 -> -0.55 | J16: =MAX(0,MIN(10,10*(C16/D16))) -> 0
A17: Senior Management (EEA2 L2) | B17: =S_Data!L6 -> 0 | C17: =IFERROR((S_Data!B6+S_Data!C6+S_Data!D6+S_Data!F6+S_Data!G6+S_Data!H6)/S_Data!L6,0) -> 0 | D17: 0.55 | E17: =IFERROR((S_Data!F6+S_Data!G6+S_Data!H6)/S_Data!L6,0) -> 0 | F17: 0.3 | G17: =0 -> 0 | H17: 0.02 | I17: =C17-D17 -> -0.55 | J17: =MAX(0,MIN(10,10*(C17/D17))) -> 0
A18: Professionally Qualified (EEA2 L3) | B18: =S_Data!L7 -> 0 | C18: =IFERROR((S_Data!B7+S_Data!C7+S_Data!D7+S_Data!F7+S_Data!G7+S_Data!H7)/S_Data!L7,0) -> 0 | D18: 0.55 | E18: =IFERROR((S_Data!F7+S_Data!G7+S_Data!H7)/S_Data!L7,0) -> 0 | F18: 0.3 | G18: =0 -> 0 | H18: 0.02 | I18: =C18-D18 -> -0.55 | J18: =MAX(0,MIN(10,10*(C18/D18))) -> 0
A19: Skilled Technical (EEA2 L4) | B19: =S_Data!L8 -> 0 | C19: =IFERROR((S_Data!B8+S_Data!C8+S_Data!D8+S_Data!F8+S_Data!G8+S_Data!H8)/S_Data!L8,0) -> 0 | D19: 0.55 | E19: =IFERROR((S_Data!F8+S_Data!G8+S_Data!H8)/S_Data!L8,0) -> 0 | F19: 0.3 | G19: =0 -> 0 | H19: 0.02 | I19: =C19-D19 -> -0.55 | J19: =MAX(0,MIN(10,10*(C19/D19))) -> 0
A20: Semi-Skilled (EEA2 L5) | B20: =S_Data!L9 -> 0 | C20: =IFERROR((S_Data!B9+S_Data!C9+S_Data!D9+S_Data!F9+S_Data!G9+S_Data!H9)/S_Data!L9,0) -> 0 | D20: 0.55 | E20: =IFERROR((S_Data!F9+S_Data!G9+S_Data!H9)/S_Data!L9,0) -> 0 | F20: 0.3 | G20: =0 -> 0 | H20: 0.02 | I20: =C20-D20 -> -0.55 | J20: =MAX(0,MIN(10,10*(C20/D20))) -> 0
A21: Unskilled (EEA2 L6) | B21: =S_Data!L10 -> 0 | C21: =IFERROR((S_Data!B10+S_Data!C10+S_Data!D10+S_Data!F10+S_Data!G10+S_Data!H10)/S_Data!L10,0) -> 0 | D21: 0.55 | E21: =IFERROR((S_Data!F10+S_Data!G10+S_Data!H10)/S_Data!L10,0) -> 0 | F21: 0.3 | G21: =0 -> 0 | H21: 0.02 | I21: =C21-D21 -> -0.55 | J21: =MAX(0,MIN(10,10*(C21/D21))) -> 0
J22: =AVERAGE(J16,J17,J18,J19,J20,J21) -> 0
A24: HEALTH & SAFETY [ISO 45001 | Source: Accidently system | Cority report | Driver debrief]
A25: H&S Metric | B25: Unit | C25: Q1 Jul-Sep | D25: Q2 Oct-Dec | E25: Q3 Jan-Mar | F25: Q4 Apr-Jun | G25: YTD | H25: Target
A26: Total employees (for LTIFR calc) | B26: headcount | C26: 426 | D26: 426 | E26: 426 | F26: 426 | G26: 426 | H26: < 2.0 | I26: Source: Coba HR data, 426 FTE excl. labour brokers (constant across quarters pending monthly updates)
A27: Hours worked YTD | B27: hours | C27: 0 | D27: 0 | E27: 0 | F27: 0 | G27: =SUM(C27:F27) -> 0
A28: Fatalities YTD | B28: count | C28: — | D28: — | E28: — | F28: — | G28: — | H28: 0
A29: Lost Time Injuries YTD | B29: count | C29: 1 | D29: 2 | E29: 1 | F29: 0 | G29: =SUM(C29:F29) -> 4 | I29: Source: SHE Incidents register Jul-25 to Apr-26 (Wallace Arends, Ndumiso Mkhize, Joseph Sebeko, Tendani Matumba)
A30: Medical Treatment Injuries (MTI) | B30: count | C30: 0 | D30: 0 | E30: 3 | F30: 0 | G30: =SUM(C30:F30) -> 3
